Workbook

Sheet 1_Response Summary
A1: BSI.IT.27.C7 - evaluation of the management response (C7.Sample.xlsx) to the A6 / A5 sample request - 10 accounts
A3: # | B3: Account | C3: Name | D3: Tested for | E3: Certification decision (decision date) | F3: Decision date | G3: Access removed (date) | H3: Business days to removal | I3: SLA deadline (30 business days) | J3: Removed within 30-business-day SLA? | K3: Next decision: 2026 Q1 | L3: 2026 Q2 SOX Manager cert (sample file) | M3: 2026 Q2 CyberArk Manager cert (sample file) | N3: Privileged network / PAM access still held in 2026 Q2 | O3: IAMS Termination Date (2026 Q2 export) | P3: AD status - prior extracts | Q3: AD enabled 10/10/2026 (sample file) | R3: Access remained removed after remediation? | S3: Evidence in the sample file | T3: Evidence still missing | U3: Conclusion
A4: 1 | B4: MIA25142 | C4: Miguel Nieves Nieves | D4: A6 Revocation within SLA | E4: Revoked 08/28/2025 (2025 Q3, Borges, Dayam) - Cisco Network Administrators, ISEAdmin | F4: 45897 | G4: 45902 | H4: =NETWORKDAYS(F4+1,G4,Holidays!$A$4:$A$23) -> 2 | I4: =WORKDAY(F4,30,Holidays!$A$4:$A$23) -> 45940 | J4: =IF(G4<=I4,"Yes - within SLA","No - late") -> Yes - within SLA | K4: Approved 04/30/2026 (re-granted, E3) | L4: Approved - 3 rows - Borges, Dayam 7/27/26, 12:45 PM (rows 98-100) | M4: Approved - 3 rows - Borges, Dayam 8/17/26, 9:23 AM (rows 431-433) | N4: Alero_Consultant_MIA25142; CISCO NETWORK ADMINISTRATORS; CYBERARK_ALERO_USERS; ISEADMIN; CyberArk Owner cert: 12 safe rows for its Alero safe (Heredia, Evelio Alejandro, 8/27/26) | O4: 2024-12-31 | P4: Enabled; member again in AD 11/25/2025 | Q4: True (Oct10_2026Users row 1621) | R4: No - present again in AD 11/25/2025, re-approved 04/30/2026 and still certified (Approved) in the 2026 Q2 SOX and CyberArk Manager certifications in the sample file | S4: C7.Sample.xlsx: SAMPLE tab screenshots; 2026Q2PamBsiSox-Manager; 2026Q2BsiPamCyberark-Manager; Oct10_2026Users row 1621; Screenshot tab (Get-ADUser export command). | T4: Netwrix "member removed" log for the 2025 Q3 revocation (only in prior-period evidence); Netwrix / AD audit "member added" event and the approved ServiceNow access request for the re-grant (between the removal date and 11/25/2025); ServiceNow revocation ticket; AD group-membership extract (Get-ADGroupMember) - the 10/10/2026 extract has no group data | U4: ="Exception (A6 - E3) NOT cleared. Removal was within the SLA ("&H4&" business days) but did not stay in place. The sample file shows no new revocation and no removal date; it shows the access approved again in 2026 Q2. Management to provide the re-grant request / approval or treat as an unauthorized re-grant." -> Exception (A6 - E3) NOT cleared. Removal was within the SLA (2 business days) but did not stay in place. The sample file shows no new revocation and no removal date; it shows the access approved again in 2026 Q2. Management to provide the re-grant request / approval or treat as an unauthorized re-grant.
A5: 2 | B5: MIA25172 | C5: Juan Hernandez Ruiz | D5: A6 Revocation within SLA | E5: Revoked 08/28/2025 (2025 Q3, Borges, Dayam) - Cisco Network Administrators | F5: 45897 | G5: 45902 | H5: =NETWORKDAYS(F5+1,G5,Holidays!$A$4:$A$23) -> 2 | I5: =WORKDAY(F5,30,Holidays!$A$4:$A$23) -> 45940 | J5: =IF(G5<=I5,"Yes - within SLA","No - late") -> Yes - within SLA | K5: Approved 04/30/2026 (re-granted, E3) | L5: Approved - 3 rows - Borges, Dayam 7/27/26, 12:45 PM (rows 140-142) | M5: Approved - 2 rows - Borges, Dayam 8/17/26, 9:23 AM (rows 467-468) | N5: CISCO NETWORK ADMINISTRATORS; CYBERARK_ALERO_USERS; ISEADMIN; CyberArk Owner cert: 12 safe rows for its Alero safe (Heredia, Evelio Alejandro, 8/27/26) | O5: - | P5: Enabled; member again in AD 11/25/2025 | Q5: True (Oct10_2026Users row 1643) | R5: No - present again in AD 11/25/2025, re-approved 04/30/2026 and still certified (Approved) in the 2026 Q2 SOX and CyberArk Manager certifications in the sample file | S5: C7.Sample.xlsx: SAMPLE tab screenshots; 2026Q2PamBsiSox-Manager; 2026Q2BsiPamCyberark-Manager; Oct10_2026Users row 1643; Screenshot tab (Get-ADUser export command). | T5: Netwrix "member removed" log for the 2025 Q3 revocation (only in prior-period evidence); Netwrix / AD audit "member added" event and the approved ServiceNow access request for the re-grant (between the removal date and 11/25/2025); ServiceNow revocation ticket; AD group-membership extract (Get-ADGroupMember) - the 10/10/2026 extract has no group data | U5: ="Exception (A6 - E3) NOT cleared. Removal was within the SLA ("&H5&" business days) but did not stay in place. The sample file shows no new revocation and no removal date; it shows the access approved again in 2026 Q2. Management to provide the re-grant request / approval or treat as an unauthorized re-grant." -> Exception (A6 - E3) NOT cleared. Removal was within the SLA (2 business days) but did not stay in place. The sample file shows no new revocation and no removal date; it shows the access approved again in 2026 Q2. Management to provide the re-grant request / approval or treat as an unauthorized re-grant.
A6: 3 | B6: MIA25175 | C6: Carlos Hernandez Acevedo | D6: A6 Revocation within SLA | E6: Revoked 08/28/2025 (2025 Q3, Borges, Dayam) - Cisco Network Administrators | F6: 45897 | G6: 45908 | H6: =NETWORKDAYS(F6+1,G6,Holidays!$A$4:$A$23) -> 6 | I6: =WORKDAY(F6,30,Holidays!$A$4:$A$23) -> 45940 | J6: =IF(G6<=I6,"Yes - within SLA","No - late") -> Yes - within SLA | K6: Approved 04/30/2026 (re-granted, E3) | L6: Approved - 3 rows - Borges, Dayam 7/27/26, 12:45 PM (rows 143-145) | M6: Approved - 3 rows - Borges, Dayam 8/17/26, 9:23 AM (rows 469-471) | N6: Alero_Consultant_MIA25175; CISCO NETWORK ADMINISTRATORS; CYBERARK_ALERO_USERS; ISEADMIN; CyberArk Owner cert: 12 safe rows for its Alero safe (Heredia, Evelio Alejandro, 8/27/26) | O6: - | P6: Enabled; member again in AD 11/25/2025 | Q6: True (Oct10_2026Users row 1644) | R6: No - present again in AD 11/25/2025, re-approved 04/30/2026 and still certified (Approved) in the 2026 Q2 SOX and CyberArk Manager certifications in the sample file | S6: C7.Sample.xlsx: SAMPLE tab screenshots; 2026Q2PamBsiSox-Manager; 2026Q2BsiPamCyberark-Manager; Oct10_2026Users row 1644; Screenshot tab (Get-ADUser export command). | T6: Netwrix "member removed" log for the 2025 Q3 revocation (only in prior-period evidence); Netwrix / AD audit "member added" event and the approved ServiceNow access request for the re-grant (between the removal date and 11/25/2025); ServiceNow revocation ticket; AD group-membership extract (Get-ADGroupMember) - the 10/10/2026 extract has no group data | U6: ="Exception (A6 - E3) NOT cleared. Removal was within the SLA ("&H6&" business days) but did not stay in place. The sample file shows no new revocation and no removal date; it shows the access approved again in 2026 Q2. Management to provide the re-grant request / approval or treat as an unauthorized re-grant." -> Exception (A6 - E3) NOT cleared. Removal was within the SLA (6 business days) but did not stay in place. The sample file shows no new revocation and no removal date; it shows the access approved again in 2026 Q2. Management to provide the re-grant request / approval or treat as an unauthorized re-grant.
A7: 4 | B7: X453396 | C7: Juan Fernando Perez Peralta | D7: A6 Revocation within SLA | E7: Revoked 08/28/2025 (2025 Q3, Borges, Dayam) - Cisco Network Administrators, ISEAdmin | F7: 45897 | G7: 45908 | H7: =NETWORKDAYS(F7+1,G7,Holidays!$A$4:$A$23) -> 6 | I7: =WORKDAY(F7,30,Holidays!$A$4:$A$23) -> 45940 | J7: =IF(G7<=I7,"Yes - within SLA","No - late") -> Yes - within SLA | K7: Approved 04/30/2026 (re-granted, E3) | L7: Approved - 3 rows - Borges, Dayam 7/27/26, 12:45 PM (rows 110-112) | M7: Approved - 3 rows - Borges, Dayam 8/17/26, 9:23 AM (rows 443-445) | N7: Alero_Protect-x453396; CISCO NETWORK ADMINISTRATORS; CYBERARK_ALERO_USERS; ISEADMIN; CyberArk Owner cert: 12 safe rows for its Alero safe (Heredia, Evelio Alejandro, 8/27/26) | O7: - | P7: Enabled; member again in AD 11/25/2025 | Q7: True (Oct10_2026Users row 1835) | R7: No - present again in AD 11/25/2025, re-approved 04/30/2026 and still certified (Approved) in the 2026 Q2 SOX and CyberArk Manager certifications in the sample file | S7: C7.Sample.xlsx: SAMPLE tab screenshots; 2026Q2PamBsiSox-Manager; 2026Q2BsiPamCyberark-Manager; Oct10_2026Users row 1835; Screenshot tab (Get-ADUser export command). | T7: Netwrix "member removed" log for the 2025 Q3 revocation (only in prior-period evidence); Netwrix / AD audit "member added" event and the approved ServiceNow access request for the re-grant (between the removal date and 11/25/2025); ServiceNow revocation ticket; AD group-membership extract (Get-ADGroupMember) - the 10/10/2026 extract has no group data | U7: ="Exception (A6 - E3) NOT cleared. Removal was within the SLA ("&H7&" business days) but did not stay in place. The sample file shows no new revocation and no removal date; it shows the access approved again in 2026 Q2. Management to provide the re-grant request / approval or treat as an unauthorized re-grant." -> Exception (A6 - E3) NOT cleared. Removal was within the SLA (6 business days) but did not stay in place. The sample file shows no new revocation and no removal date; it shows the access approved again in 2026 Q2. Management to provide the re-grant request / approval or treat as an unauthorized re-grant.
A8: 5 | B8: MIA25103 | C8: Ivan Ramirez Gonzalez | D8: A5 / supporting - account status | E8: Approved 08/28/2025 (2025 Q3, Borges, Dayam) | F8: N/A | G8: N/A - not revoked | H8: N/A | I8: N/A | J8: N/A - no revocation decision | K8: Approved 04/30/2026 | L8: Approved - 3 rows - Borges, Dayam 7/27/26, 12:45 PM (rows 86-88) | M8: Approved - 3 rows - Borges, Dayam 8/17/26, 9:23 AM (rows 419-421) | N8: Alero_Consultant_MIA25103; CISCO NETWORK ADMINISTRATORS; CYBERARK_ALERO_USERS; ISEADMIN; CyberArk Owner cert: 12 safe rows for its Alero safe (Heredia, Evelio Alejandro, 8/27/26) | O8: 2024-12-31 | P8: Disabled 11/25/2025 and 05/15/2026 (last logon 10/15/2023) | Q8: False (Oct10_2026Users row 1598) | R8: N/A - never revoked (Approved in 2025 Q3, 2026 Q1 and 2026 Q2) | S8: C7.Sample.xlsx: SAMPLE tab screenshots; 2026Q2PamBsiSox-Manager; 2026Q2BsiPamCyberark-Manager; Oct10_2026Users row 1598; Screenshot tab (Get-ADUser export command). | T8: HR / vendor contract evidence that the engagement was active on each decision date (IAMS shows termination 12/31/2024); rationale for approving terminated / AD-disabled identities; AD audit (whenChanged / Netwrix) for the enable / disable history; ServiceNow ticket or exception record; group-membership extract | U8: Exception (A5 - E1, E2) NOT cleared. Account is disabled in AD (11/25/2025, 05/15/2026 and 10/10/2026), yet its Cisco Network Administrators / ISEAdmin access was approved again in 2026 Q2 (7/27/2026, 8/17/2026). IAMS termination 12/31/2024. No revocation raised.
A9: 6 | B9: MIA25104 | C9: Jefferson Paez Venegas | D9: A5 / supporting - account status | E9: Approved 08/28/2025 (2025 Q3, Borges, Dayam) | F9: N/A | G9: N/A - not revoked | H9: N/A | I9: N/A | J9: N/A - no revocation decision | K9: Approved 04/30/2026 | L9: Approved - 3 rows - Borges, Dayam 7/27/26, 12:45 PM (rows 89-91) | M9: Approved - 3 rows - Borges, Dayam 8/17/26, 9:23 AM (rows 422-424) | N9: Alero_Consultant_MIA25104; CISCO NETWORK ADMINISTRATORS; CYBERARK_ALERO_USERS; ISEADMIN; CyberArk Owner cert: 12 safe rows for its Alero safe (Heredia, Evelio Alejandro, 8/27/26) | O9: 2024-12-31 | P9: Enabled 11/25/2025 and 05/15/2026 | Q9: True (Oct10_2026Users row 1596) | R9: N/A - never revoked (Approved in 2025 Q3, 2026 Q1 and 2026 Q2) | S9: C7.Sample.xlsx: SAMPLE tab screenshots; 2026Q2PamBsiSox-Manager; 2026Q2BsiPamCyberark-Manager; Oct10_2026Users row 1596; Screenshot tab (Get-ADUser export command). | T9: HR / vendor contract evidence that the engagement was active on each decision date (IAMS shows termination 12/31/2024); rationale for approving terminated / AD-disabled identities; AD audit (whenChanged / Netwrix) for the enable / disable history; ServiceNow ticket or exception record; group-membership extract | U9: Exception (A5 - E2) NOT cleared. Access was approved, not revoked, so there is no removal or SLA to test. IAMS still shows termination 12/31/2024 in 2026 Q2 and the access was re-approved.
A10: 7 | B10: MIA25105 | C10: David Serrano Aguirre | D10: A5 / supporting - account status | E10: Approved 08/28/2025 (2025 Q3, Borges, Dayam) | F10: N/A | G10: N/A - not revoked | H10: N/A | I10: N/A | J10: N/A - no revocation decision | K10: Approved 04/30/2026 | L10: Approved - 3 rows - Borges, Dayam 7/27/26, 12:45 PM (rows 92-94) | M10: Approved - 3 rows - Borges, Dayam 8/17/26, 9:23 AM (rows 425-427) | N10: Alero_Consultant_MIA25105; CISCO NETWORK ADMINISTRATORS; CYBERARK_ALERO_USERS; ISEADMIN; CyberArk Owner cert: 12 safe rows for its Alero safe (Heredia, Evelio Alejandro, 8/27/26) | O10: 2024-12-31 | P10: Enabled 11/25/2025 and 05/15/2026 | Q10: True (Oct10_2026Users row 1599) | R10: N/A - never revoked (Approved in 2025 Q3, 2026 Q1 and 2026 Q2) | S10: C7.Sample.xlsx: SAMPLE tab screenshots; 2026Q2PamBsiSox-Manager; 2026Q2BsiPamCyberark-Manager; Oct10_2026Users row 1599; Screenshot tab (Get-ADUser export command). | T10: HR / vendor contract evidence that the engagement was active on each decision date (IAMS shows termination 12/31/2024); rationale for approving terminated / AD-disabled identities; AD audit (whenChanged / Netwrix) for the enable / disable history; ServiceNow ticket or exception record; group-membership extract | U10: Exception (A5 - E2) NOT cleared. Access was approved, not revoked, so there is no removal or SLA to test. IAMS still shows termination 12/31/2024 in 2026 Q2 and the access was re-approved.
A11: 8 | B11: MIA25106 | C11: Maiko Vazquez Arias | D11: A5 / supporting - account status | E11: Approved 08/28/2025 (2025 Q3, Borges, Dayam) | F11: N/A | G11: N/A - not revoked | H11: N/A | I11: N/A | J11: N/A - no revocation decision | K11: Approved 04/30/2026 | L11: Approved - 3 rows - Borges, Dayam 7/27/26, 12:45 PM (rows 95-97) | M11: Approved - 3 rows - Borges, Dayam 8/17/26, 9:23 AM (rows 428-430) | N11: Alero_Consultant_MIA25106; CISCO NETWORK ADMINISTRATORS; CYBERARK_ALERO_USERS; ISEADMIN; CyberArk Owner cert: 12 safe rows for its Alero safe (Heredia, Evelio Alejandro, 8/27/26) | O11: 2024-12-31 | P11: Enabled 11/25/2025 and 05/15/2026 | Q11: True (Oct10_2026Users row 1597) | R11: N/A - never revoked (Approved in 2025 Q3, 2026 Q1 and 2026 Q2) | S11: C7.Sample.xlsx: SAMPLE tab screenshots; 2026Q2PamBsiSox-Manager; 2026Q2BsiPamCyberark-Manager; Oct10_2026Users row 1597; Screenshot tab (Get-ADUser export command). | T11: HR / vendor contract evidence that the engagement was active on each decision date (IAMS shows termination 12/31/2024); rationale for approving terminated / AD-disabled identities; AD audit (whenChanged / Netwrix) for the enable / disable history; ServiceNow ticket or exception record; group-membership extract | U11: Exception (A5 - E2) NOT cleared. Access was approved, not revoked, so there is no removal or SLA to test. IAMS still shows termination 12/31/2024 in 2026 Q2 and the access was re-approved.
A12: 9 | B12: MIA25249 | C12: Richard Harris | D12: A5 / supporting - account status | E12: Approved 08/28/2025 (2025 Q3, Borges, Dayam) | F12: N/A | G12: N/A - not revoked | H12: N/A | I12: N/A | J12: N/A - no revocation decision | K12: Approved 04/30/2026 | L12: Approved - 3 rows - Borges, Dayam 7/27/26, 12:45 PM (rows 104-106) | M12: Approved - 3 rows - Borges, Dayam 8/17/26, 9:23 AM (rows 437-439) | N12: Alero_Consultant_MIA25249; CISCO NETWORK ADMINISTRATORS; CYBERARK_ALERO_USERS; ISEADMIN; CyberArk Owner cert: 12 safe rows for its Alero safe (Heredia, Evelio Alejandro, 8/27/26) | O12: 2024-12-31 | P12: Enabled 11/25/2025; DISABLED 05/15/2026 (changed 04/02/2026) | Q12: True (Oct10_2026Users row 1787) | R12: N/A - never revoked (Approved in 2025 Q3, 2026 Q1 and 2026 Q2) | S12: C7.Sample.xlsx: SAMPLE tab screenshots; 2026Q2PamBsiSox-Manager; 2026Q2BsiPamCyberark-Manager; Oct10_2026Users row 1787; Screenshot tab (Get-ADUser export command). | T12: HR / vendor contract evidence that the engagement was active on each decision date (IAMS shows termination 12/31/2024); rationale for approving terminated / AD-disabled identities; AD audit (whenChanged / Netwrix) for the enable / disable history; ServiceNow ticket or exception record; group-membership extract | U12: Exception (A5 - E2) NOT cleared. Access was approved, not revoked, so there is no removal or SLA to test. IAMS still shows termination 12/31/2024 in 2026 Q2 and the access was re-approved. AD shows the account disabled on 05/15/2026 and ENABLED again on 10/10/2026 - re-enable not explained or evidenced.
A13: 10 | B13: MIA25250 | C13: Kevin Ackley | D13: A5 / supporting - account status | E13: Approved 08/28/2025 (2025 Q3, Borges, Dayam) | F13: N/A | G13: N/A - not revoked | H13: N/A | I13: N/A | J13: N/A - no revocation decision | K13: Approved 04/30/2026 | L13: Approved - 3 rows - Borges, Dayam 7/27/26, 12:45 PM (rows 101-103) | M13: Approved - 3 rows - Borges, Dayam 8/17/26, 9:23 AM (rows 434-436) | N13: Alero_Protect-MIA25250; CISCO NETWORK ADMINISTRATORS; CYBERARK_ALERO_USERS; ISEADMIN; CyberArk Owner cert: 12 safe rows for its Alero safe (Heredia, Evelio Alejandro, 8/27/26) | O13: 2024-12-31 | P13: Enabled 11/25/2025; DISABLED 05/15/2026 (changed 04/03/2026) | Q13: True (Oct10_2026Users row 1785) | R13: N/A - never revoked (Approved in 2025 Q3, 2026 Q1 and 2026 Q2) | S13: C7.Sample.xlsx: SAMPLE tab screenshots; 2026Q2PamBsiSox-Manager; 2026Q2BsiPamCyberark-Manager; Oct10_2026Users row 1785; Screenshot tab (Get-ADUser export command). | T13: HR / vendor contract evidence that the engagement was active on each decision date (IAMS shows termination 12/31/2024); rationale for approving terminated / AD-disabled identities; AD audit (whenChanged / Netwrix) for the enable / disable history; ServiceNow ticket or exception record; group-membership extract | U13: Exception (A5 - E2) NOT cleared. Access was approved, not revoked, so there is no removal or SLA to test. IAMS still shows termination 12/31/2024 in 2026 Q2 and the access was re-approved. AD shows the account disabled on 05/15/2026 and ENABLED again on 10/10/2026 - re-enable not explained or evidenced. AD employeeID / employeeNumber blank on 10/10/2026; the SAMPLE tab hard-codes identity 100592068 instead of the VLOOKUP used for the other rows (A7 observation).
A15: Blue text = dates taken from the prior-period evidence (BSI.IT.27.C7.05 Testing Walkthrough tabs 4 / 5: 2025 Q3 SailPoint decision 08/28/2025 and Netwrix removal 09/02/2025 or 09/08/2025). They are NOT in C7.Sample.xlsx; they are restated so the SLA can be recalculated.
A16: Columns H-J are formulas: NETWORKDAYS / WORKDAY over the US bank holidays on the Holidays tab; SLA = 30 business days (IAM Standard v10.0 SUS.IAMS.4.2.5.21).
A17: Columns L-Q come from C7.Sample.xlsx (2026 Q2 PAM BSI SOX Manager certification launched 7/22/2026; 2026 Q2 PAM BSI CyberArk Manager certification launched 8/13/2026; AD user export Oct10_2026Users).
A18: Account Status = "Account Removed" appears on every row of all four 2026 Q2 exports (4,889 rows, including the 4,883 Approved rows), so it cannot be used as evidence of removal.
A20: Result counts
B21: Accounts tested | E21: =COUNTA(B4:B13) -> 10
B22: A6 revocations removed within SLA (2025 Q3) | E22: =COUNTIF(J4:J13,"Yes*") -> 4
B23: A6 removals sustained | E23: =COUNTIF(R4:R13,"Yes*") -> 0
B24: Accounts with an exception not cleared | E24: =COUNTIF(U4:U13,"Exception*") -> 10

Sheet 2_Item Detail
A1: Every 2026 Q2 certification row for the 10 sample accounts (account-holder rows, SOX Manager and CyberArk Manager certifications)
A3: Source tab (C7.Sample.xlsx) | B3: Source row | C3: Account | D3: Identity | E3: Identity DisplayName | F3: Entitlement Value | G3: Decision | H3: Revoke Completed | I3: Decision Maker | J3: Decision Date | K3: SignOff Date | L3: Termination Date (IAMS) | M3: Identity Inactive | N3: Account Status | O3: WorkItemID | P3: AD enabled 10/10/2026 | Q3: Self-review? | R3: Assessment
A4: 2026Q2BsiPamCyberark-Manager | B4: 431 | C4: MIA25142 | D4: 100546241 | E4: Nieves Nieves, Miguel | F4: MIA25142 Nieves Nieves,Miguelhas privileged access to CyberArk safe: Alero_Consultant_MIA25142 | G4: Approved | I4: Borges, Dayam | J4: 8/17/26, 9:23 AM | K4: 8/17/26, 9:23 AM | L4: 2024-12-31 | M4: =FALSE() -> FALSE | N4: Account Removed | O4: - | P4: =TRUE() -> TRUE | Q4: No | R4: Exception: Approved although IAMS Termination Date 2024-12-31 (E2)
A5: 2026Q2BsiPamCyberark-Manager | B5: 432 | C5: MIA25142 | D5: 100546241 | E5: Nieves Nieves, Miguel | F5: MIA25142 Nieves Nieves,Miguel has privileged access to CyberArk safe: Network_Devices_Accounts via AD Group:Cisco Network Administrators | G5: Approved | I5: Borges, Dayam | J5: 8/17/26, 9:23 AM | K5: 8/17/26, 9:23 AM | L5: 2024-12-31 | M5: =FALSE() -> FALSE | N5: Account Removed | O5: - | P5: =TRUE() -> TRUE | Q5: No | R5: Exception: Approved although IAMS Termination Date 2024-12-31 (E2); Access revoked 08/28/2025 is still held and approved again (E3 - removal not sustained)
A6: 2026Q2BsiPamCyberark-Manager | B6: 433 | C6: MIA25142 | D6: 100546241 | E6: Nieves Nieves, Miguel | F6: MIA25142 Nieves Nieves,Miguel has privileged access to CyberArk safe: Network_Devices_Accounts via AD Group:ISEAdmin | G6: Approved | I6: Borges, Dayam | J6: 8/17/26, 9:23 AM | K6: 8/17/26, 9:23 AM | L6: 2024-12-31 | M6: =FALSE() -> FALSE | N6: Account Removed | O6: - | P6: =TRUE() -> TRUE | Q6: No | R6: Exception: Approved although IAMS Termination Date 2024-12-31 (E2); Access revoked 08/28/2025 is still held and approved again (E3 - removal not sustained)
A7: 2026Q2PamBsiSox-Manager | B7: 98 | C7: MIA25142 | D7: 100546241 | E7: Nieves Nieves, Miguel | F7: MIA25142 HAS PRIVILEGED ACCESS TO SOX APPLICATIONS VIA THE MIA.USA.SINVEST ENTERPRISE WIDE DOMAIN GROUP CYBERARK_ALERO_USERS | G7: Approved | I7: Borges, Dayam | J7: 7/27/26, 12:45 PM | K7: 7/27/26, 12:45 PM | L7: 2024-12-31 | M7: =FALSE() -> FALSE | N7: Account Removed | O7: - | P7: =TRUE() -> TRUE | Q7: No | R7: Exception: Approved although IAMS Termination Date 2024-12-31 (E2)
A8: 2026Q2PamBsiSox-Manager | B8: 99 | C8: MIA25142 | D8: 100546241 | E8: Nieves Nieves, Miguel | F8: MIA25142 HAS PRIVILEGED ACCESS TO SOX APPLICATIONS VIA THE MIA.USA.SINVEST ENTERPRISE WIDE DOMAIN GROUP CISCO NETWORK ADMINISTRATORS | G8: Approved | I8: Borges, Dayam | J8: 7/27/26, 12:45 PM | K8: 7/27/26, 12:45 PM | L8: 2024-12-31 | M8: =FALSE() -> FALSE | N8: Account Removed | O8: - | P8: =TRUE() -> TRUE | Q8: No | R8: Exception: Approved although IAMS Termination Date 2024-12-31 (E2); Access revoked 08/28/2025 is still held and approved again (E3 - removal not sustained)
A9: 2026Q2PamBsiSox-Manager | B9: 100 | C9: MIA25142 | D9: 100546241 | E9: Nieves Nieves, Miguel | F9: MIA25142 HAS PRIVILEGED ACCESS TO SOX APPLICATIONS VIA THE MIA.USA.SINVEST ENTERPRISE WIDE DOMAIN GROUP ISEADMIN | G9: Approved | I9: Borges, Dayam | J9: 7/27/26, 12:45 PM | K9: 7/27/26, 12:45 PM | L9: 2024-12-31 | M9: =FALSE() -> FALSE | N9: Account Removed | O9: - | P9: =TRUE() -> TRUE | Q9: No | R9: Exception: Approved although IAMS Termination Date 2024-12-31 (E2); Access revoked 08/28/2025 is still held and approved again (E3 - removal not sustained)
A10: 2026Q2BsiPamCyberark-Manager | B10: 467 | C10: MIA25172 | D10: MIA25172 | E10: Hernandez Ruiz, Juan | F10: MIA25172 Hernandez Ruiz,Juan has privileged access to CyberArk safe: Network_Devices_Accounts via AD Group:Cisco Network Administrators | G10: Approved | I10: Borges, Dayam | J10: 8/17/26, 9:23 AM | K10: 8/17/26, 9:23 AM | L10: - | M10: =FALSE() -> FALSE | N10: Account Removed | O10: - | P10: =TRUE() -> TRUE | Q10: No | R10: Exception: Access revoked 08/28/2025 is still held and approved again (E3 - removal not sustained)
A11: 2026Q2BsiPamCyberark-Manager | B11: 468 | C11: MIA25172 | D11: MIA25172 | E11: Hernandez Ruiz, Juan | F11: MIA25172 Hernandez Ruiz,Juan has privileged access to CyberArk safe: Network_Devices_Accounts via AD Group:ISEAdmin | G11: Approved | I11: Borges, Dayam | J11: 8/17/26, 9:23 AM | K11: 8/17/26, 9:23 AM | L11: - | M11: =FALSE() -> FALSE | N11: Account Removed | O11: - | P11: =TRUE() -> TRUE | Q11: No | R11: Approved - no exception noted for this entitlement
A12: 2026Q2PamBsiSox-Manager | B12: 140 | C12: MIA25172 | D12: MIA25172 | E12: Hernandez Ruiz, Juan | F12: MIA25172 HAS PRIVILEGED ACCESS TO SOX APPLICATIONS VIA THE MIA.USA.SINVEST ENTERPRISE WIDE DOMAIN GROUP CYBERARK_ALERO_USERS | G12: Approved | I12: Borges, Dayam | J12: 7/27/26, 12:45 PM | K12: 7/27/26, 12:45 PM | L12: - | M12: =FALSE() -> FALSE | N12: Account Removed | O12: - | P12: =TRUE() -> TRUE | Q12: No | R12: Approved - no exception noted for this entitlement
A13: 2026Q2PamBsiSox-Manager | B13: 141 | C13: MIA25172 | D13: MIA25172 | E13: Hernandez Ruiz, Juan | F13: MIA25172 HAS PRIVILEGED ACCESS TO SOX APPLICATIONS VIA THE MIA.USA.SINVEST ENTERPRISE WIDE DOMAIN GROUP CISCO NETWORK ADMINISTRATORS | G13: Approved | I13: Borges, Dayam | J13: 7/27/26, 12:45 PM | K13: 7/27/26, 12:45 PM | L13: - | M13: =FALSE() -> FALSE | N13: Account Removed | O13: - | P13: =TRUE() -> TRUE | Q13: No | R13: Exception: Access revoked 08/28/2025 is still held and approved again (E3 - removal not sustained)
A14: 2026Q2PamBsiSox-Manager | B14: 142 | C14: MIA25172 | D14: MIA25172 | E14: Hernandez Ruiz, Juan | F14: MIA25172 HAS PRIVILEGED ACCESS TO SOX APPLICATIONS VIA THE MIA.USA.SINVEST ENTERPRISE WIDE DOMAIN GROUP ISEADMIN | G14: Approved | I14: Borges, Dayam | J14: 7/27/26, 12:45 PM | K14: 7/27/26, 12:45 PM | L14: - | M14: =FALSE() -> FALSE | N14: Account Removed | O14: - | P14: =TRUE() -> TRUE | Q14: No | R14: Approved - no exception noted for this entitlement
A15: 2026Q2BsiPamCyberark-Manager | B15: 469 | C15: MIA25175 | D15: MIA25175 | E15: Hernandez Acevedo, Carlos | F15: MIA25175 Hernandez Acevedo,Carlos has privileged access to CyberArk safe: Network_Devices_Accounts via AD Group:Cisco Network Administrators | G15: Approved | I15: Borges, Dayam | J15: 8/17/26, 9:23 AM | K15: 8/17/26, 9:23 AM | L15: - | M15: =FALSE() -> FALSE | N15: Account Removed | O15: - | P15: =TRUE() -> TRUE | Q15: No | R15: Exception: Access revoked 08/28/2025 is still held and approved again (E3 - removal not sustained)
A16: 2026Q2BsiPamCyberark-Manager | B16: 470 | C16: MIA25175 | D16: MIA25175 | E16: Hernandez Acevedo, Carlos | F16: MIA25175 Hernandez Acevedo,Carlos has privileged access to CyberArk safe: Network_Devices_Accounts via AD Group:ISEAdmin | G16: Approved | I16: Borges, Dayam | J16: 8/17/26, 9:23 AM | K16: 8/17/26, 9:23 AM | L16: - | M16: =FALSE() -> FALSE | N16: Account Removed | O16: - | P16: =TRUE() -> TRUE | Q16: No | R16: Approved - no exception noted for this entitlement
A17: 2026Q2BsiPamCyberark-Manager | B17: 471 | C17: MIA25175 | D17: MIA25175 | E17: Hernandez Acevedo, Carlos | F17: MIA25175 Hernandez Acevedo,Carloshas privileged access to CyberArk safe: Alero_Consultant_MIA25175 | G17: Approved | I17: Borges, Dayam | J17: 8/17/26, 9:23 AM | K17: 8/17/26, 9:23 AM | L17: - | M17: =FALSE() -> FALSE | N17: Account Removed | O17: - | P17: =TRUE() -> TRUE | Q17: No | R17: Approved - no exception noted for this entitlement
A18: 2026Q2PamBsiSox-Manager | B18: 143 | C18: MIA25175 | D18: MIA25175 | E18: Hernandez Acevedo, Carlos | F18: MIA25175 HAS PRIVILEGED ACCESS TO SOX APPLICATIONS VIA THE MIA.USA.SINVEST ENTERPRISE WIDE DOMAIN GROUP CYBERARK_ALERO_USERS | G18: Approved | I18: Borges, Dayam | J18: 7/27/26, 12:45 PM | K18: 7/27/26, 12:45 PM | L18: - | M18: =FALSE() -> FALSE | N18: Account Removed | O18: - | P18: =TRUE() -> TRUE | Q18: No | R18: Approved - no exception noted for this entitlement
A19: 2026Q2PamBsiSox-Manager | B19: 144 | C19: MIA25175 | D19: MIA25175 | E19: Hernandez Acevedo, Carlos | F19: MIA25175 HAS PRIVILEGED ACCESS TO SOX APPLICATIONS VIA THE MIA.USA.SINVEST ENTERPRISE WIDE DOMAIN GROUP CISCO NETWORK ADMINISTRATORS | G19: Approved | I19: Borges, Dayam | J19: 7/27/26, 12:45 PM | K19: 7/27/26, 12:45 PM | L19: - | M19: =FALSE() -> FALSE | N19: Account Removed | O19: - | P19: =TRUE() -> TRUE | Q19: No | R19: Exception: Access revoked 08/28/2025 is still held and approved again (E3 - removal not sustained)
A20: 2026Q2PamBsiSox-Manager | B20: 145 | C20: MIA25175 | D20: MIA25175 | E20: Hernandez Acevedo, Carlos | F20: MIA25175 HAS PRIVILEGED ACCESS TO SOX APPLICATIONS VIA THE MIA.USA.SINVEST ENTERPRISE WIDE DOMAIN GROUP ISEADMIN | G20: Approved | I20: Borges, Dayam | J20: 7/27/26, 12:45 PM | K20: 7/27/26, 12:45 PM | L20: - | M20: =FALSE() -> FALSE | N20: Account Removed | O20: - | P20: =TRUE() -> TRUE | Q20: No | R20: Approved - no exception noted for this entitlement
A21: 2026Q2BsiPamCyberark-Manager | B21: 443 | C21: X453396 | D21: 100611758 | E21: Perez Peralta, Juan Fernando | F21: x453396 Perez Peralta,Juan Fernandohas privileged access to CyberArk safe: Alero_Protect-x453396 | G21: Approved | I21: Borges, Dayam | J21: 8/17/26, 9:23 AM | K21: 8/17/26, 9:23 AM | L21: - | M21: =FALSE() -> FALSE | N21: Account Removed | O21: - | P21: =TRUE() -> TRUE | Q21: No | R21: Approved - no exception noted for this entitlement
A22: 2026Q2BsiPamCyberark-Manager | B22: 444 | C22: X453396 | D22: 100611758 | E22: Perez Peralta, Juan Fernando | F22: x453396 Perez Peralta,Juan Fernando has privileged access to CyberArk safe: Network_Devices_Accounts via AD Group:Cisco Network Administrators | G22: Approved | I22: Borges, Dayam | J22: 8/17/26, 9:23 AM | K22: 8/17/26, 9:23 AM | L22: - | M22: =FALSE() -> FALSE | N22: Account Removed | O22: - | P22: =TRUE() -> TRUE | Q22: No | R22: Exception: Access revoked 08/28/2025 is still held and approved again (E3 - removal not sustained)
A23: 2026Q2BsiPamCyberark-Manager | B23: 445 | C23: X453396 | D23: 100611758 | E23: Perez Peralta, Juan Fernando | F23: x453396 Perez Peralta,Juan Fernando has privileged access to CyberArk safe: Network_Devices_Accounts via AD Group:ISEAdmin | G23: Approved | I23: Borges, Dayam | J23: 8/17/26, 9:23 AM | K23: 8/17/26, 9:23 AM | L23: - | M23: =FALSE() -> FALSE | N23: Account Removed | O23: - | P23: =TRUE() -> TRUE | Q23: No | R23: Exception: Access revoked 08/28/2025 is still held and approved again (E3 - removal not sustained)
A24: 2026Q2PamBsiSox-Manager | B24: 110 | C24: X453396 | D24: 100611758 | E24: Perez Peralta, Juan Fernando | F24: X453396 HAS PRIVILEGED ACCESS TO SOX APPLICATIONS VIA THE MIA.USA.SINVEST ENTERPRISE WIDE DOMAIN GROUP CYBERARK_ALERO_USERS | G24: Approved | I24: Borges, Dayam | J24: 7/27/26, 12:45 PM | K24: 7/27/26, 12:45 PM | L24: - | M24: =FALSE() -> FALSE | N24: Account Removed | O24: - | P24: =TRUE() -> TRUE | Q24: No | R24: Approved - no exception noted for this entitlement
A25: 2026Q2PamBsiSox-Manager | B25: 111 | C25: X453396 | D25: 100611758 | E25: Perez Peralta, Juan Fernando | F25: X453396 HAS PRIVILEGED ACCESS TO SOX APPLICATIONS VIA THE MIA.USA.SINVEST ENTERPRISE WIDE DOMAIN GROUP CISCO NETWORK ADMINISTRATORS | G25: Approved | I25: Borges, Dayam | J25: 7/27/26, 12:45 PM | K25: 7/27/26, 12:45 PM | L25: - | M25: =FALSE() -> FALSE | N25: Account Removed | O25: - | P25: =TRUE() -> TRUE | Q25: No | R25: Exception: Access revoked 08/28/2025 is still held and approved again (E3 - removal not sustained)
A26: 2026Q2PamBsiSox-Manager | B26: 112 | C26: X453396 | D26: 100611758 | E26: Perez Peralta, Juan Fernando | F26: X453396 HAS PRIVILEGED ACCESS TO SOX APPLICATIONS VIA THE MIA.USA.SINVEST ENTERPRISE WIDE DOMAIN GROUP ISEADMIN | G26: Approved | I26: Borges, Dayam | J26: 7/27/26, 12:45 PM | K26: 7/27/26, 12:45 PM | L26: - | M26: =FALSE() -> FALSE | N26: Account Removed | O26: - | P26: =TRUE() -> TRUE | Q26: No | R26: Exception: Access revoked 08/28/2025 is still held and approved again (E3 - removal not sustained)
A27: 2026Q2BsiPamCyberark-Manager | B27: 419 | C27: MIA25103 | D27: 100531048 | E27: Ramirez Gonzalez, Ivan | F27: MIA25103 Ivan Ramirez Gonzalez has privileged access to CyberArk safe: Network_Devices_Accounts via AD Group:Cisco Network Administrators | G27: Approved | I27: Borges, Dayam | J27: 8/17/26, 9:23 AM | K27: 8/17/26, 9:23 AM | L27: 2024-12-31 | M27: =FALSE() -> FALSE | N27: Account Removed | O27: - | P27: =FALSE() -> FALSE | Q27: No | R27: Exception: Approved although IAMS Termination Date 2024-12-31 (E2); Approved although AD account disabled (E1)
A28: 2026Q2BsiPamCyberark-Manager | B28: 420 | C28: MIA25103 | D28: 100531048 | E28: Ramirez Gonzalez, Ivan | F28: MIA25103 Ivan Ramirez Gonzalez has privileged access to CyberArk safe: Network_Devices_Accounts via AD Group:ISEAdmin | G28: Approved | I28: Borges, Dayam | J28: 8/17/26, 9:23 AM | K28: 8/17/26, 9:23 AM | L28: 2024-12-31 | M28: =FALSE() -> FALSE | N28: Account Removed | O28: - | P28: =FALSE() -> FALSE | Q28: No | R28: Exception: Approved although IAMS Termination Date 2024-12-31 (E2); Approved although AD account disabled (E1)
A29: 2026Q2BsiPamCyberark-Manager | B29: 421 | C29: MIA25103 | D29: 100531048 | E29: Ramirez Gonzalez, Ivan | F29: MIA25103 Ivan Ramirez Gonzalezhas privileged access to CyberArk safe: Alero_Consultant_MIA25103 | G29: Approved | I29: Borges, Dayam | J29: 8/17/26, 9:23 AM | K29: 8/17/26, 9:23 AM | L29: 2024-12-31 | M29: =FALSE() -> FALSE | N29: Account Removed | O29: - | P29: =FALSE() -> FALSE | Q29: No | R29: Exception: Approved although IAMS Termination Date 2024-12-31 (E2); Approved although AD account disabled (E1)
A30: 2026Q2PamBsiSox-Manager | B30: 86 | C30: MIA25103 | D30: 100531048 | E30: Ramirez Gonzalez, Ivan | F30: MIA25103 HAS PRIVILEGED ACCESS TO SOX APPLICATIONS VIA THE MIA.USA.SINVEST ENTERPRISE WIDE DOMAIN GROUP CYBERARK_ALERO_USERS | G30: Approved | I30: Borges, Dayam | J30: 7/27/26, 12:45 PM | K30: 7/27/26, 12:45 PM | L30: 2024-12-31 | M30: =FALSE() -> FALSE | N30: Account Removed | O30: - | P30: =FALSE() -> FALSE | Q30: No | R30: Exception: Approved although IAMS Termination Date 2024-12-31 (E2); Approved although AD account disabled (E1)
A31: 2026Q2PamBsiSox-Manager | B31: 87 | C31: MIA25103 | D31: 100531048 | E31: Ramirez Gonzalez, Ivan | F31: MIA25103 HAS PRIVILEGED ACCESS TO SOX APPLICATIONS VIA THE MIA.USA.SINVEST ENTERPRISE WIDE DOMAIN GROUP CISCO NETWORK ADMINISTRATORS | G31: Approved | I31: Borges, Dayam | J31: 7/27/26, 12:45 PM | K31: 7/27/26, 12:45 PM | L31: 2024-12-31 | M31: =FALSE() -> FALSE | N31: Account Removed | O31: - | P31: =FALSE() -> FALSE | Q31: No | R31: Exception: Approved although IAMS Termination Date 2024-12-31 (E2); Approved although AD account disabled (E1)
A32: 2026Q2PamBsiSox-Manager | B32: 88 | C32: MIA25103 | D32: 100531048 | E32: Ramirez Gonzalez, Ivan | F32: MIA25103 HAS PRIVILEGED ACCESS TO SOX APPLICATIONS VIA THE MIA.USA.SINVEST ENTERPRISE WIDE DOMAIN GROUP ISEADMIN | G32: Approved | I32: Borges, Dayam | J32: 7/27/26, 12:45 PM | K32: 7/27/26, 12:45 PM | L32: 2024-12-31 | M32: =FALSE() -> FALSE | N32: Account Removed | O32: - | P32: =FALSE() -> FALSE | Q32: No | R32: Exception: Approved although IAMS Termination Date 2024-12-31 (E2); Approved although AD account disabled (E1)
A33: 2026Q2BsiPamCyberark-Manager | B33: 422 | C33: MIA25104 | D33: 100531049 | E33: Paez Venegas, Jefferson | F33: MIA25104 Paez Venegas,Jeffersonhas privileged access to CyberArk safe: Alero_Consultant_MIA25104 | G33: Approved | I33: Borges, Dayam | J33: 8/17/26, 9:23 AM | K33: 8/17/26, 9:23 AM | L33: 2024-12-31 | M33: =FALSE() -> FALSE | N33: Account Removed | O33: - | P33: =TRUE() -> TRUE | Q33: No | R33: Exception: Approved although IAMS Termination Date 2024-12-31 (E2)
A34: 2026Q2BsiPamCyberark-Manager | B34: 423 | C34: MIA25104 | D34: 100531049 | E34: Paez Venegas, Jefferson | F34: MIA25104 Paez Venegas,Jefferson has privileged access to CyberArk safe: Network_Devices_Accounts via AD Group:Cisco Network Administrators | G34: Approved | I34: Borges, Dayam | J34: 8/17/26, 9:23 AM | K34: 8/17/26, 9:23 AM | L34: 2024-12-31 | M34: =FALSE() -> FALSE | N34: Account Removed | O34: - | P34: =TRUE() -> TRUE | Q34: No | R34: Exception: Approved although IAMS Termination Date 2024-12-31 (E2)
A35: 2026Q2BsiPamCyberark-Manager | B35: 424 | C35: MIA25104 | D35: 100531049 | E35: Paez Venegas, Jefferson | F35: MIA25104 Paez Venegas,Jefferson has privileged access to CyberArk safe: Network_Devices_Accounts via AD Group:ISEAdmin | G35: Approved | I35: Borges, Dayam | J35: 8/17/26, 9:23 AM | K35: 8/17/26, 9:23 AM | L35: 2024-12-31 | M35: =FALSE() -> FALSE | N35: Account Removed | O35: - | P35: =TRUE() -> TRUE | Q35: No | R35: Exception: Approved although IAMS Termination Date 2024-12-31 (E2)
A36: 2026Q2PamBsiSox-Manager | B36: 89 | C36: MIA25104 | D36: 100531049 | E36: Paez Venegas, Jefferson | F36: MIA25104 HAS PRIVILEGED ACCESS TO SOX APPLICATIONS VIA THE MIA.USA.SINVEST ENTERPRISE WIDE DOMAIN GROUP CYBERARK_ALERO_USERS | G36: Approved | I36: Borges, Dayam | J36: 7/27/26, 12:45 PM | K36: 7/27/26, 12:45 PM | L36: 2024-12-31 | M36: =FALSE() -> FALSE | N36: Account Removed | O36: - | P36: =TRUE() -> TRUE | Q36: No | R36: Exception: Approved although IAMS Termination Date 2024-12-31 (E2)
A37: 2026Q2PamBsiSox-Manager | B37: 90 | C37: MIA25104 | D37: 100531049 | E37: Paez Venegas, Jefferson | F37: MIA25104 HAS PRIVILEGED ACCESS TO SOX APPLICATIONS VIA THE MIA.USA.SINVEST ENTERPRISE WIDE DOMAIN GROUP CISCO NETWORK ADMINISTRATORS | G37: Approved | I37: Borges, Dayam | J37: 7/27/26, 12:45 PM | K37: 7/27/26, 12:45 PM | L37: 2024-12-31 | M37: =FALSE() -> FALSE | N37: Account Removed | O37: - | P37: =TRUE() -> TRUE | Q37: No | R37: Exception: Approved although IAMS Termination Date 2024-12-31 (E2)
A38: 2026Q2PamBsiSox-Manager | B38: 91 | C38: MIA25104 | D38: 100531049 | E38: Paez Venegas, Jefferson | F38: MIA25104 HAS PRIVILEGED ACCESS TO SOX APPLICATIONS VIA THE MIA.USA.SINVEST ENTERPRISE WIDE DOMAIN GROUP ISEADMIN | G38: Approved | I38: Borges, Dayam | J38: 7/27/26, 12:45 PM | K38: 7/27/26, 12:45 PM | L38: 2024-12-31 | M38: =FALSE() -> FALSE | N38: Account Removed | O38: - | P38: =TRUE() -> TRUE | Q38: No | R38: Exception: Approved although IAMS Termination Date 2024-12-31 (E2)
A39: 2026Q2BsiPamCyberark-Manager | B39: 425 | C39: MIA25105 | D39: 100531050 | E39: Serrano Aguirre, David | F39: MIA25105 Serrano Aguirre,Davidhas privileged access to CyberArk safe: Alero_Consultant_MIA25105 | G39: Approved | I39: Borges, Dayam | J39: 8/17/26, 9:23 AM | K39: 8/17/26, 9:23 AM | L39: 2024-12-31 | M39: =FALSE() -> FALSE | N39: Account Removed | O39: - | P39: =TRUE() -> TRUE | Q39: No | R39: Exception: Approved although IAMS Termination Date 2024-12-31 (E2)
A40: 2026Q2BsiPamCyberark-Manager | B40: 426 | C40: MIA25105 | D40: 100531050 | E40: Serrano Aguirre, David | F40: MIA25105 Serrano Aguirre,David has privileged access to CyberArk safe: Network_Devices_Accounts via AD Group:Cisco Network Administrators | G40: Approved | I40: Borges, Dayam | J40: 8/17/26, 9:23 AM | K40: 8/17/26, 9:23 AM | L40: 2024-12-31 | M40: =FALSE() -> FALSE | N40: Account Removed | O40: - | P40: =TRUE() -> TRUE | Q40: No | R40: Exception: Approved although IAMS Termination Date 2024-12-31 (E2)
A41: 2026Q2BsiPamCyberark-Manager | B41: 427 | C41: MIA25105 | D41: 100531050 | E41: Serrano Aguirre, David | F41: MIA25105 Serrano Aguirre,David has privileged access to CyberArk safe: Network_Devices_Accounts via AD Group:ISEAdmin | G41: Approved | I41: Borges, Dayam | J41: 8/17/26, 9:23 AM | K41: 8/17/26, 9:23 AM | L41: 2024-12-31 | M41: =FALSE() -> FALSE | N41: Account Removed | O41: - | P41: =TRUE() -> TRUE | Q41: No | R41: Exception: Approved although IAMS Termination Date 2024-12-31 (E2)
...

Sheet 3_Step-by-Step
A1: Step-by-step test procedure (9 steps) applied to the management response C7.Sample.xlsx
A3: Step | B3: Procedure | C3: Source (C7.Sample.xlsx tab / field) | D3: What was done | E3: Result obtained | F3: Step result
A4: 1 | B4: STEP 1 - OBTAIN EVIDENCE | C4: All tabs; Screenshot tab | D4: Inventoried the response to the 10-account request: certification exports, AD extract, screenshots. | E4: Received: 2026 Q2 PAM BSI SOX Manager (188 rows, launched 7/22/2026) and SOX Entitlement Owner (336 rows, 7/23/2026); 2026 Q2 PAM BSI CyberArk Manager (680 rows, 8/13/2026) and CyberArk Entitlement Owner (3,685 rows, 8/14/2026); AD user export Oct10_2026Users (2,543 accounts); 20 SAMPLE-tab screenshots of the filtered certification rows; screenshot of the Get-ADUser command. NOT received: Netwrix logs, AD audit logs, ServiceNow tickets, removal dates, group-membership extract, re-grant access requests, HR / contract evidence. The 2026 Q2 campaigns were launched after the period end (06/30/2026) and are subsequent-period evidence. | F4: Observation - response incomplete
A5: 2 | B5: STEP 2 - VALIDATE REPORT COMPLETENESS AND ACCURACY | C5: Oct10_2026Users; Screenshot tab; certification exports | D5: Tried to reconcile the certified network-group memberships to AD and checked the report generation evidence. | E5: Cannot be performed: the AD export has user attributes only (name, sAMAccountName, enabled, UPN, employeeID, employeeNumber) - no group membership, whenChanged or account expiration - so certified memberships cannot be reconciled to Cisco Network Administrators / ISEAdmin / CISCO ISE Administrators / F5FullAdmin. Report reliability observations: (a) the export is named Oct10_2026 but the command screenshot is time-stamped 10/13/2026 11:04 AM - the link between the screenshot and the file is not shown; (b) MIA25250 has blank employeeID / employeeNumber, and the SAMPLE tab hard-codes 100592068 instead of the VLOOKUP; (c) Account Status = "Account Removed" on every row, including approved access; (d) 1 AD row has a blank enabled value; (e) MIA25172 and MIA25175 are uncorrelated - Identity = account name (not employee number 100546248 / 100546251) in both 2026 Q2 Manager certifications, so IAMS status is not evaluated for them; (f) SOX = No on every sample row, including the SOX Manager certification. | F5: Observation (A7)
A6: 3 | B6: STEP 3 - VALIDATE POPULATION AND SCOPE | C6: 2026Q2PamBsiSox-Manager / -Owner, Entitlement Value | D6: Parsed the 4 in-scope network groups (PAM Definition of Privilege sec. 3.3) from Entitlement Value. | E6: 2026 Q2 SOX certifications: 58 in-scope memberships (Manager 48 - Cisco Net Admins 23, ISEAdmin 22, F5FullAdmin 2, CISCO ISE Admins 1; Owner 10). All 10 sample accounts are in the population (Cisco Network Administrators, ISEAdmin, CYBERARK_ALERO_USERS). Completeness against AD cannot be concluded (see step 2). | F6: Partial - completeness not evidenced
A7: 4 | B7: STEP 4 - VERIFY CONTROL EXECUTION | C7: Certification Name, Decision Maker, Decision / SignOff Date | D7: For the 10 accounts: initiation, reviewer, decision, revocations identified. | E7: Initiation: 2026 Q2 SOX campaign launched 7/22/2026, CyberArk 8/13/2026 (SanIAM / SailPoint). Reviewer: line manager Borges, Dayam (SOX 7/27/2026 12:45 PM; CyberArk 8/17/2026 9:23 AM); Alero safes by owner Heredia, Evelio Alejandro (8/27/2026); no self-review. Decisions: 59 / 59 account-holder rows Approved and signed off. Revocations identified: none for the 10 accounts. Inappropriate access approved: 7 identities with IAMS Termination Date 12/31/2024 (MIA25103-06, MIA25142, MIA25249, MIA25250); MIA25103 disabled in AD; 4 accounts whose 2025 Q3 revocation was reversed (MIA25142, MIA25172, MIA25175, X453396). Population-wide in the 2026 Q2 SOX Manager cert: 8 network-group members disabled in AD on 10/10/2026 still Approved (MIA20037, MIA25103, X533062, X688027, X689040, X689379, X690623, X690995). | F7: Fail (A5)
A8: 5 | B8: STEP 5 - VALIDATE CONTROL RESULTS | C8: 1_Response Summary cols F-J, R | D8: For the 4 A6 accounts: decision date, removal date, SLA, persistence. | E8: Decision 08/28/2025 (2025 Q3 Revoked). Removal 09/02/2025 (MIA25142, MIA25172) and 09/08/2025 (MIA25175, X453396) per the prior Netwrix logs = 2 and 6 business days, within the SLA deadline of 10/10/2025. Persistence: NOT sustained - the sample file shows all 4 still holding Cisco Network Administrators / ISEAdmin and approved again in 2026 Q2. The response provides no removal date, Netwrix log or ticket. The 6 supplemental accounts were never revoked, so no SLA applies. | F8: Fail (A6 - persistence)
A9: 6 | B9: STEP 6 - VERIFY EXCEPTION HANDLING | C9: All tabs; WorkItemID / WorkItemComment | D9: Looked for exception records, comments or tickets for the 10 accounts. | E9: WorkItemID / WorkItemComment are blank for all 59 rows; no exception record, risk acceptance or comment. The response does not explain the re-grants or the approvals of terminated / disabled identities. | F9: Fail (not evidenced)
A10: 7 | B10: STEP 7 - VERIFY ESCALATION AND REMEDIATION | C10: All tabs | D10: Looked for escalation, remediation owner, due date and tracking. | E10: None provided. The same exceptions found in 2025 Q3 and 2026 Q1 recur in 2026 Q2 (third consecutive review), so remediation is not evidenced. MIA25249 / MIA25250 went from disabled (05/15/2026) to enabled (10/10/2026) with no explanation. | F10: Fail (not evidenced)
A11: 8 | B11: STEP 8 - ASSESS RISK MITIGATION | C11: 1_Response Summary; 2_Item Detail | D11: Does the review identify inappropriate access and drive timely, lasting revocation? | E11: No for the tested accounts. Reviews run and are signed off by the right reviewers, but the reviewer re-approves terminated, disabled and previously revoked privileged network access, and revocations are not sustained. Privileged network access for these 10 accounts remains in place as of the 2026 Q2 certifications. | F11: Fail - Needs Improvement
A12: 9 | B12: STEP 9 - SUMMARIZE TESTING COVERAGE | C12: This tab | D12: Coverage per attribute. | E12: Completeness & accuracy: Observation (no group data). Scope: Partial. Initiation: Pass. Reviewer authorization: Pass. Certification execution: Pass. Revocation decisions / appropriateness: Fail. Timeliness of removal: Pass (2025 Q3, 2 and 6 business days). Persistence: Fail. Exception management: Fail. Escalation: Fail. Risk mitigation: Fail. The response does not clear any of the 10 exceptions; the prior conclusion (Needs Improvement) stands. | F12: Fail - Needs Improvement

Sheet 4_Open Items
A1: Evidence still needed after the C7.Sample.xlsx response
A3: # | B3: Account(s) | C3: Request | D3: Why it is needed | E3: Owner | F3: Status
A4: 1 | B4: MIA25142, MIA25172, MIA25175, X453396 | C4: Netwrix "member removed" events for the 2025 Q3 revocations (09/02/2025, 09/08/2025) and the "member added" events that put the accounts back in Cisco Network Administrators / ISEAdmin, with date and actor. | D4: Only system evidence that dates the removal and the re-grant. | E4: InfoSec (Netwrix) | F4: Pending
A5: 2 | B5: MIA25142, MIA25172, MIA25175, X453396 | C5: Approved ServiceNow access request (manager + group owner) for each re-grant, or confirmation that none exists. | D5: Only evidence that can clear E3. | E5: PAM / IAM | F5: Pending
A6: 3 | B6: All 10 | C6: Get-ADGroupMember export of Cisco Network Administrators, ISEAdmin, CISCO ISE Administrators, F5FullAdmin and CYBERARK_ALERO_USERS, with the command screenshot (date / time visible), plus whenChanged and accountExpires for the 10 accounts. | D6: The 10/10/2026 user export has no group or change data, so it cannot show whether access was removed or stayed removed. | E6: IT Ops / InfoSec | F6: Pending
A7: 4 | B7: MIA25103-06, MIA25142, MIA25249, MIA25250 | C7: HR / vendor contract dates and the reason IAMS still shows Termination Date 12/31/2024; reviewer rationale for approving these identities on 7/27/2026 and 8/17/2026. | D7: Decides whether E2 is a real exception or an IAMS data-quality observation. | E7: HR / IAM / Control owner | F7: Pending
A8: 5 | B8: MIA25103 | C8: Why a disabled AD account keeps (and is re-approved for) privileged network group membership; removal ticket. | D8: E1 - disabled account approved in three reviews. | E8: PAM / IAM | F8: Pending
A9: 6 | B9: MIA25249, MIA25250 | C9: AD audit / Netwrix event and approved request for the re-enable between 05/15/2026 (disabled) and 10/10/2026 (enabled). | D9: Unexplained re-enable of accounts with privileged network access. | E9: IT Ops / InfoSec | F9: Pending
A10: 7 | B10: MIA25250 | C10: Explain the blank employeeID / employeeNumber in AD and the hard-coded identity 100592068 in the SAMPLE tab. | D10: Identity correlation between AD and SanIAM (A7). | E10: IAM | F10: Pending
A11: 8 | B11: All 10 | C11: Exception / issue record, escalation, remediation owner and due date (ServiceNow or GRC). | D11: Steps 6-7 cannot pass without it. | E11: Control owner | F11: Pending
A12: 9 | B12: MIA25172, MIA25175 | C12: Correlate both accounts to their SanIAM identity (AD employeeNumber 100546248 / 100546251). In both 2026 Q2 Manager certifications the Identity field holds the account name, so IAMS termination / inactive status cannot be checked. | D12: Uncorrelated accounts escape identity-based leaver controls (A7). | E12: IAM | F12: Pending
A13: 10 | B13: All | C13: Explain why Account Status = "Account Removed" on every row of the certification exports. | D13: Field cannot be relied on (A7). | E13: IAM | F13: Pending

Sheet 5_Follow-up Email
A1: Draft follow-up to the control owner
A3: Hi Zoila,
A5: Thank you for sending C7.Sample.xlsx. We reviewed it against the request for the 10 sampled accounts. It contains the 2026 Q2 PAM BSI SOX and CyberArk certification exports, the 10/10/2026 AD user export and screenshots. It does not yet answer the A6 questions, and for all 10 accounts it shows the access still in place.
A7: What the file shows:
A8: - MIA25142, MIA25172, MIA25175, X453396: revoked on 08/28/2025 (2025 Q3) and removed on 09/02/2025 or 09/08/2025, within the 30-business-day SLA. However, all four still hold Cisco Network Administrators / ISEAdmin and were approved again in the 2026 Q2 SOX Manager certification (Borges, Dayam, 7/27/2026) and the CyberArk Manager certification (8/17/2026). The access did not stay removed, and the file has no removal date, Netwrix log or ticket for a later removal.
A9: - MIA25103, MIA25104, MIA25105, MIA25106, MIA25249, MIA25250: approved again in 2026 Q2. None of these accounts was revoked, so there is no removal date or SLA to test. IAMS still shows Termination Date 12/31/2024 for all six. MIA25103 is disabled in AD but still approved. MIA25249 and MIA25250 were disabled on 05/15/2026 and are enabled again on 10/10/2026.
A11: To complete the testing, please provide:
A12: 1. Netwrix / AD audit events for the removal (09/02/2025, 09/08/2025) and for the re-addition of MIA25142, MIA25172, MIA25175 and X453396 to Cisco Network Administrators / ISEAdmin, with dates, plus the approved access request (ServiceNow) for each re-grant.
A13: 2. A Get-ADGroupMember export of Cisco Network Administrators, ISEAdmin, CISCO ISE Administrators, F5FullAdmin and CYBERARK_ALERO_USERS, with the command screenshot showing date and time, plus whenChanged / accountExpires for the 10 accounts. The 10/10/2026 export has no group data, so it cannot show whether access was removed.
A14: 3. HR or contract evidence for MIA25103-06, MIA25142, MIA25249 and MIA25250, given the IAMS termination date of 12/31/2024, and the reviewer's rationale for approving them.
A15: 4. The reason, and approval, for MIA25103's disabled account keeping network admin access, and for the re-enable of MIA25249 / MIA25250.
A16: 5. Any exception, escalation or remediation record (owner, due date, status) for these accounts.
... A21: Edward Morfa

Sheet 6_Sources
A1: Sources used
A3: File | B3: Tab | C3: Content | D3: Used for | E3: MD5
A4: C7.Sample.xlsx | B4: SAMPLE | C4: Sample list, VLOOKUP to AD employeeNumber, 20 screenshots of filtered SOX / CyberArk Manager rows | D4: Sample identification | E4: 5338b068e48afaf6f3d7b185ac6cf12e
A5: C7.Sample.xlsx | B5: 2026Q2PamBsiSox-Manager | C5: 2026 Q2 PAM BSI SOX Manager Certification [7/22/26] - 188 rows | D5: Decision / reviewer / dates | E5: 5338b068e48afaf6f3d7b185ac6cf12e
A6: C7.Sample.xlsx | B6: 2026Q2PamBsiSox-Owner | C6: 2026 Q2 PAM BSI SOX Entitlement Owner Certification [7/23/26] - 336 rows | D6: Population / scope | E6: 5338b068e48afaf6f3d7b185ac6cf12e
A7: C7.Sample.xlsx | B7: 2026Q2BsiPamCyberark-Manager | C7: 2026 Q2 PAM BSI CyberArk Manager Certification [8/13/26] - 680 rows | D7: Decision / reviewer / dates | E7: 5338b068e48afaf6f3d7b185ac6cf12e
A8: C7.Sample.xlsx | B8: 2026Q2PamBsiCyberark-Owner | C8: 2026 Q2 PAM BSI CyberArk Entitlement Owner Certification [8/14/26] - 3,685 rows | D8: Alero safe owner review | E8: 5338b068e48afaf6f3d7b185ac6cf12e
A9: C7.Sample.xlsx | B9: Oct10_2026Users | C9: Get-ADUser export (2,543 accounts; enabled, UPN, employeeID / Number) | D9: AD account status | E9: 5338b068e48afaf6f3d7b185ac6cf12e
A10: C7.Sample.xlsx | B10: Screenshot | C10: PowerShell ISE - Get-ADUser -Filter * export command, 10/13/2026 11:04 AM | D10: Report generation (A7) | E10: 5338b068e48afaf6f3d7b185ac6cf12e
A11: BSI.IT.27.C7.05 Testing Walkthrough - Step by Step.xlsx | B11: 4_Item Detail, 5_Exceptions | C11: Prior testing: 2025 Q3 decisions 08/28/2025, Netwrix removals 09/02 / 09/08/2025, AD 11/25/2025 and 05/15/2026 | D11: Decision and removal dates for A6; prior exceptions | E11: a6eee02a47888234ca2afd7662f0fd49
A12: CUSO Identity and Access Management Standard v11.0 (BSIIT21.PDF) | B12: sec. 4.2.4, 4.2.5, Appendix G | C12: Approved 07/28/2026; SUS.IAMS.4.2.4.2 / 4.2.4.3 leaver SLAs (1 / 30 business days from termination); 4.2.5.7 / 4.2.5.21 review revocation SLA (30 business days from close of review) | D12: Which SLA applies (tab 7) | E12: 35484fd4951ac6439d9e4aee56437c38
A13: PAM_Recertification_Procedure_BSI_04.22.26.pdf | B13: sec. 3, 4.1.1, 8 step 9-10 | C13: v2.0 approved 04/22/2026; revocation tickets for reject decisions or terminated users; process ends when manager approves | D13: Which SLA applies (tab 7) | E13: 9eaef168c42e8bd6bdd088432f6bf75a
A14: Sample step taken.docx | B14: - | C14: Request to the control owner (A6 sample, 10 accounts) | D14: Request being answered | E14: 478b98cad0b66e5989c71e3ee9f1bef3

Sheet 7_SLA Re-performance
A1: SLA re-performance for the 6 supplemental accounts, based on the IAM Standard and the PAM Recertification Procedure (responds to the process owner's challenge)
A3: A. Process owner's challenge
A4: "If the access is approved, what SLA is being measured? The SLA only starts if the access is revoked. Approved access has no action; only revoked access needs action. The workpaper says none of the 6 accounts was revoked, so the SLA clock never started, but then concludes 'No - SLA not met' using the first review after termination as the trigger date."
A6: B. Policy analysis - which SLA applies to the 6 accounts
A7: # | B7: Question | D7: Policy text (exact) | H7: Reference | I7: Assessment | K7: Conclusion
A8: 1 | B8: Does the 30-business-day review SLA apply to access that was approved? | D8: "Any revocation of privileged access rights resulting from the privileged access review outcomes must be completed within 30 business days of the close of the review per the SLA." (4.2.5.21) "Any revocations of access rights must be completed within 30 business days per the SLA." (4.2.5.7) "When all assignees have completed their decisions, if the manager approves the user access, the process ends." (PAM step 9) | H8: CUSO Identity and Access Management Standard v11.0 (approved 07/28/2026) SUS.IAMS.4.2.5.21 (p.22), SUS.IAMS.4.2.5.7 (p.18); BSI PAM Recertification Procedure v2.0 (approved 04/22/2026) sec. 4.1.1 C3-C4 (p.6), sec. 8 step 9 (p.10) | I8: No. The 30-business-day clock starts at the close of the review and only for a revocation that results from the review outcome. All 6 accounts were Approved in every review, so no revocation was raised and no SLA clock started. | K8: Process owner is CORRECT. The prior "No - SLA not met (211 business days)" result is WITHDRAWN. A6 (revocation within SLA) = N/A for the 6 accounts.
A9: 2 | B9: Did the procedure still require these accounts to be revoked at the review? | D9: "If access is revoked, the PAM team submits revocation tickets for any 'reject' decision or terminated users." (PAM step 9) "The recertification process must be performed as a formal review of information assets to confirm that all granted access rights entitlements remain valid" (4.2.5.1) | H9: BSI PAM Recertification Procedure v2.0 (approved 04/22/2026) sec. 8 step 9 (p.10), sec. 3 PAM US Team; CUSO Identity and Access Management Standard v11.0 (approved 07/28/2026) SUS.IAMS.4.2.5.1 (p.14) | I9: Yes, if the identities were terminated. Step 9 names terminated users alongside reject decisions as a revocation trigger, and 4.2.5.1 requires the review to confirm access remains valid. IAMS shows Termination Date 12/31/2024 for all 6; the reviewer approved and PAM raised no revocation ticket in 2025 Q3, 2026 Q1 or 2026 Q2. | K9: Exception stands as A5 (appropriateness / control execution), NOT as an SLA (A6) failure: the review did not identify and revoke access of terminated identities.
A10: 3 | B10: Is there an SLA for terminated users that does not depend on a Revoked decision? | D10: "Network Access for terminated users must be in line with the SLAs defined in the SLA matrix" (4.2.4.2) - Appendix G: disable AD access, 1 business day. "Privileged access and control plane access for terminated users must be in line with the SLAs defined in the SLA matrix ... If ... the SLA is missed, initiate a look-back assessment" (4.2.4.3) - Appendix G: 30 business days. | H10: CUSO Identity and Access Management Standard v11.0 (approved 07/28/2026) SUS.IAMS.4.2.4.2 and 4.2.4.3 (p.12-13), Appendix G SLA Matrix (p.46, 53) | I10: Yes, but it is the leaver (de-provisioning) SLA, triggered by the termination date and owned by IAM/PAM under 4.2.4 - not by the C7 review. If the 12/31/2024 termination is confirmed, the deadlines were 01/02/2025 (AD) and 02/13/2025 (privileged access) and both were missed; a look-back of use after termination is required. | K10: Not rated in C7 A6. Report as an observation and refer to the leaver / de-provisioning control owner, pending HR confirmation (item 4).
A11: 4 | B11: Is the 12/31/2024 termination real? | D11: IAMS: Termination Date 12/31/2024, Identity Inactive = FALSE, Assignee Employee Status = A (2026 Q2 exports). AD: expiration 01/01/2026 then 06/01/2026, logons in Nov 2025 (walkthrough). CyberArk safes are named Alero_Consultant_* / Alero_Protect-* (external consultants). | H11: C7.Sample.xlsx 2026 Q2 Manager tabs; walkthrough 4_Item Detail, 7_Evidence Status #4 | I11: Not confirmed. The data suggest consultants whose contract end date was not updated in IAMS after an extension. HR / vendor contract evidence is still outstanding. | K11: If contracts were active: items 2-3 become an IAMS data-quality observation, except MIA25103 (below). If terminated: A5 exception + leaver SLA observation.
A12: 5 | B12: MIA25103 (Ivan Ramirez Gonzalez) - AD disabled | D12: AD enabled = FALSE on 11/25/2025, 05/15/2026 and 10/10/2026; last logon 10/15/2023. Still a member of Cisco Network Administrators / ISEAdmin and approved on 7/27/2026 and 8/17/2026. | H12: C7.Sample.xlsx Oct10_2026Users row 1598; Sox-Manager rows 86-88; CyberArk-Manager rows 419-421 | I12: Disabled account kept privileged network group membership and was re-approved. The review SLA does not apply (no revocation), but the review failed to identify an inactive account. | K12: Exception A5 (E1) stands regardless of the HR outcome.
A14: C. Re-performance per account - three tests (formulas in green-shaded result columns)
