Workbook

Sheet DRL
A1: Document Request List (DRL) - 2026 IT RCSA Cycle 1 - Configuration Management / Malware Protection Controls
A2: Please upload each item to the control's evidence folder using the Request # in the file name (e.g., 'C11-04 <server name>.txt'). System-generated reports must show the query/filters, run date and user who ran them. Sample-level items (marked 'For each ... sample') will be requested once IT RCSA selects samples from the population. Control owner: complete the yellow columns (Date Provided, Status, Control Owner Comments).
A4: Control # | B4: Control Statement | C4: Request # | D4: Evidence Request/Description | E4: Coverage Period | F4: NewTest Script Step | G4: Prior (2025) Evidence Reference | H4: Control Owner | I4: Date Provided | J4: Status | K4: Control Owner Comments
A5: BSI.IT.10.C11 | B5: [BSI.IT.10.C11 Vendor Defaults] In every operation, Infrastructure teams change vendor default passwords for root or administrator accounts on Operating Systems before the server reaches install status in CMDB. | C5: C11-01 | D5: Current Windows Server and Red Hat Enterprise Linux (RHEL) hardening guides / server build procedures showing the requirement to change vendor default credentials for the built-in Administrator, Guest and root accounts, and the step in the build process (before the server reaches 'Install' status in CMDB) where this is performed. | E5: ='Coverage Period'!K6 -> 07/01/2025 - 06/30/2026 | F5: 1. Obtain Evidence | G5: 2025 WP2 Test Procedure steps 1-2 | H5: Ian Rojo
A6: BSI.IT.10.C11 | B6: [BSI.IT.10.C11 Vendor Defaults] In every operation, Infrastructure teams change vendor default passwords for root or administrator accounts on Operating Systems before the server reaches install status in CMDB. | C6: C11-02 | D6: System-generated CMDB (ServiceNow) report of ALL BSI Windows and RHEL servers that reached 'Install' status during the coverage period. Include: server name, OS and version, environment (Prod/Non-Prod), entity, created date and date moved to Install status. Provide a screenshot of the query/filters, run date and run-by user (IPE). | E6: ='Coverage Period'!K6 -> 07/01/2025 - 06/30/2026 | F6: 3. Population & Scope | G6: 2025 population: 417 Windows & Linux servers from CMDB | H6: Ian Rojo
A7: BSI.IT.10.C11 | B7: [BSI.IT.10.C11 Vendor Defaults] In every operation, Infrastructure teams change vendor default passwords for root or administrator accounts on Operating Systems before the server reaches install status in CMDB. | C7: C11-03 | D7: Control owner's completeness & accuracy check over the CMDB report in the prior item (e.g., reconciliation of the CMDB server list to Active Directory computer objects / virtualization console for the same period). | E7: ='Coverage Period'!K6 -> 07/01/2025 - 06/30/2026 | F7: 2. Report Completeness & Accuracy | G7: New for 2026 (RCSA Procedure - IPE validation) | H7: Ian Rojo
A8: BSI.IT.10.C11 | B8: [BSI.IT.10.C11 Vendor Defaults] In every operation, Infrastructure teams change vendor default passwords for root or administrator accounts on Operating Systems before the server reaches install status in CMDB. | C8: C11-04 | D8: For each Windows server sample selected by IT RCSA from the population: security policy export (secedit /export /cfg c:\security_export.txt) or equivalent screenshot showing NewAdministratorName and NewGuestName changed from the vendor default and Guest account disabled. File name must contain the server name; export date visible. | E8: ='Coverage Period'!K6 -> 07/01/2025 - 06/30/2026 | F8: 4. Control Execution | G8: BSI.IT.10.C11.05 Windows sample | H8: Ian Rojo
A9: BSI.IT.10.C11 | B9: [BSI.IT.10.C11 Vendor Defaults] In every operation, Infrastructure teams change vendor default passwords for root or administrator accounts on Operating Systems before the server reaches install status in CMDB. | C9: C11-05 | D9: For each Windows server sample: evidence that the local Administrator password was changed from the vendor default before the CMDB Install date (e.g., LAPS password last-set / expiration attribute, or PAM vault onboarding record with date). | E9: ='Coverage Period'!K6 -> 07/01/2025 - 06/30/2026 | F9: 4. Control Execution | G9: New for 2026 - timing attribute in revised control statement | H9: Ian Rojo
A10: BSI.IT.10.C11 | B10: [BSI.IT.10.C11 Vendor Defaults] In every operation, Infrastructure teams change vendor default passwords for root or administrator accounts on Operating Systems before the server reaches install status in CMDB. | C10: C11-06 | D10: For each RHEL server sample: command output with hostname and date visible for (a) grep PermitRootLogin /etc/ssh/sshd_config and (b) passwd -S root or chage -l root showing root password status / last change date relative to the CMDB Install date. | E10: ='Coverage Period'!K6 -> 07/01/2025 - 06/30/2026 | F10: 4. Control Execution | G10: BSI.IT.10.C11.06 Linux Servers | H10: Ian Rojo
A11: BSI.IT.10.C11 | B11: [BSI.IT.10.C11 Vendor Defaults] In every operation, Infrastructure teams change vendor default passwords for root or administrator accounts on Operating Systems before the server reaches install status in CMDB. | C11: C11-07 | D11: List of any servers where vendor defaults could not be changed during the coverage period, with documented business justification and approval. If none, written confirmation from the control owner. | E11: ='Coverage Period'!K6 -> 07/01/2025 - 06/30/2026 | F11: 6. Exception Handling | G11: 2025: none noted | H11: Ian Rojo
A12: BSI.IT.10.C11 | B12: [BSI.IT.10.C11 Vendor Defaults] In every operation, Infrastructure teams change vendor default passwords for root or administrator accounts on Operating Systems before the server reaches install status in CMDB. | C12: C11-08 | D12: Tickets / vulnerability or configuration-scan findings (e.g., Qualys) raised during the coverage period for default or unchanged root/administrator credentials, with remediation evidence and closure dates. If none, written confirmation. | E12: ='Coverage Period'!K6 -> 07/01/2025 - 06/30/2026 | F12: 7. Escalation & Remediation | G12: New for 2026 | H12: Ian Rojo
A13: BSI.IT.10.C12 | B13: [BSI.IT.10.C12 Encrypt Endpoint Device] In every operation, prior to assigning a user a computer, the End User Technology (EUT) team encrypts endpoints with approved encryption algorithms and lengths. | C13: C12-01 | D13: Current Encryption / Cryptography Standard listing the approved encryption algorithms and key lengths for end-user computers (Windows and macOS). | E13: ='Coverage Period'!K7 -> 06/01/2025 - 05/31/2026 | F13: 1. Obtain Evidence | G13: New for 2026 - 'approved encryption algorithms and lengths' | H13: Cesar Rubio
A14: BSI.IT.10.C12 | B14: [BSI.IT.10.C12 Encrypt Endpoint Device] In every operation, prior to assigning a user a computer, the End User Technology (EUT) team encrypts endpoints with approved encryption algorithms and lengths. | C14: C12-02 | D14: EUT procedure for imaging (Windows) and assignment (macOS) of user computers, showing that encryption is applied before a device is assigned and that devices which cannot be imaged/encrypted are not assigned. | E14: ='Coverage Period'!K7 -> 06/01/2025 - 05/31/2026 | F14: 1. Obtain Evidence | G14: 2025 WP2 control description | H14: Cesar Rubio
A15: BSI.IT.10.C12 | B15: [BSI.IT.10.C12 Encrypt Endpoint Device] In every operation, prior to assigning a user a computer, the End User Technology (EUT) team encrypts endpoints with approved encryption algorithms and lengths. | C15: C12-03 | D15: Screenshot of the production Windows imaging task sequence (SCCM/MECM or Intune Autopilot) showing the encryption step(s) (e.g., 'Deploy MNE BitLocker' / 'Install Drive Encryption'), with last-modified date. | E15: ='Coverage Period'!K7 -> 06/01/2025 - 05/31/2026 | F15: 4. Control Execution | G15: BSI.IT.10.C12.03 Encryption task and algorithm | H15: Cesar Rubio
A16: BSI.IT.10.C12 | B16: [BSI.IT.10.C12 Encrypt Endpoint Device] In every operation, prior to assigning a user a computer, the End User Technology (EUT) team encrypts endpoints with approved encryption algorithms and lengths. | C16: C12-04 | D16: Screenshot of the encryption policy configuration (GPO / Intune / Trellix ePO) showing the enforced encryption method and key length (e.g., BitLocker XTS-AES 256); for macOS, the FileVault enforcement configuration profile in the MDM. | E16: ='Coverage Period'!K7 -> 06/01/2025 - 05/31/2026 | F16: 4. Control Execution | G16: BSI.IT.10.C12.03 Encryption task and algorithm | H16: Cesar Rubio
A17: BSI.IT.10.C12 | B17: [BSI.IT.10.C12 Encrypt Endpoint Device] In every operation, prior to assigning a user a computer, the End User Technology (EUT) team encrypts endpoints with approved encryption algorithms and lengths. | C17: C12-05 | D17: System-generated report of all user computers imaged and/or assigned to users during the coverage period: device name, OS, image date, assigned user and assignment date. Include query/filter screenshot and run date (IPE). | E17: ='Coverage Period'!K7 -> 06/01/2025 - 05/31/2026 | F17: 3. Population & Scope | G17: New for 2026 - supports 'prior to assigning' attribute | H17: Cesar Rubio
A18: BSI.IT.10.C12 | B18: [BSI.IT.10.C12 Encrypt Endpoint Device] In every operation, prior to assigning a user a computer, the End User Technology (EUT) team encrypts endpoints with approved encryption algorithms and lengths. | C18: C12-06 | D18: Encryption compliance report (Intune / MBAM / Trellix ePO) for all BSI endpoints as of the request date: device name, encryption status, encryption method and key length. Include report parameters and run date. List any devices still on legacy Trellix native encryption (AES-256-CBC) and the BitLocker transition status. | E18: ='Coverage Period'!K7 -> 06/01/2025 - 05/31/2026 | F18: 5. Control Results | G18: 2025 WP2 Summary of Results item 2 | H18: Cesar Rubio
A19: BSI.IT.10.C12 | B19: [BSI.IT.10.C12 Encrypt Endpoint Device] In every operation, prior to assigning a user a computer, the End User Technology (EUT) team encrypts endpoints with approved encryption algorithms and lengths. | C19: C12-07 | D19: For the sample device selected by IT RCSA: manage-bde -status (Windows) or fdesetup status (macOS) output showing Protection On and encryption method/key length, with device name and date visible, plus the asset assignment record showing assignment date. | E19: ='Coverage Period'!K7 -> 06/01/2025 - 05/31/2026 | F19: 5. Control Results | G19: 2025 sample: laptop screenshot XTS-AES 256 | H19: Cesar Rubio
A20: BSI.IT.10.C12 | B20: [BSI.IT.10.C12 Encrypt Endpoint Device] In every operation, prior to assigning a user a computer, the End User Technology (EUT) team encrypts endpoints with approved encryption algorithms and lengths. | C20: C12-08 | D20: Change history for the imaging task sequence and encryption policy during the coverage period (change tickets / ePO or Intune audit log), to confirm the automated configuration was unchanged or changes were approved (automated-control baseline). | E20: ='Coverage Period'!K7 -> 06/01/2025 - 05/31/2026 | F20: 2. Report Completeness & Accuracy | G20: New for 2026 | H20: Cesar Rubio
A21: BSI.IT.10.C12 | B21: [BSI.IT.10.C12 Encrypt Endpoint Device] In every operation, prior to assigning a user a computer, the End User Technology (EUT) team encrypts endpoints with approved encryption algorithms and lengths. | C21: C12-09 | D21: List of devices that could not be encrypted or re-imaged during the coverage period and evidence they were not assigned to users, or approved exceptions. If none, written confirmation. | E21: ='Coverage Period'!K7 -> 06/01/2025 - 05/31/2026 | F21: 6. Exception Handling | G21: 2025: none noted | H21: Cesar Rubio
A22: BSI.IT.10.C13 | B22: [BSI.IT.10.C13 Config Authentication] In every operation, Infrastructure Engineering have configured strong authentication settings/policies for operating systems on premise to align with the Authentication and Authorization Standard. Exception to authentication configurations must be approved by the CISO. | C22: C13-01 | D22: Current Authentication and Authorization Standard and the Windows Server and RHEL hardening guides showing required values for: minimum password length, complexity, minimum/maximum password age, password history, failed-login lockout threshold, lockout duration, reset lockout counter and idle session timeout. | E22: ='Coverage Period'!K8 -> 07/05/2025 - 01/04/2026 | F22: 1. Obtain Evidence | G22: 2025 WP2 Test Procedure step 3 | H22: Ian Rojo
A23: BSI.IT.10.C13 | B23: [BSI.IT.10.C13 Config Authentication] In every operation, Infrastructure Engineering have configured strong authentication settings/policies for operating systems on premise to align with the Authentication and Authorization Standard. Exception to authentication configurations must be approved by the CISO. | C23: C13-02 | D23: System-generated inventory (CMDB) of ALL on-premise BSI Windows and Linux (RHEL) servers in scope during the coverage period: server name, OS/version, environment, status. Include query/filter screenshot and run date (IPE). | E23: ='Coverage Period'!K8 -> 07/05/2025 - 01/04/2026 | F23: 3. Population & Scope | G23: BSI.IT.10.C13.04 Server inventory (416 servers) | H23: Ian Rojo
A24: BSI.IT.10.C13 | B24: [BSI.IT.10.C13 Config Authentication] In every operation, Infrastructure Engineering have configured strong authentication settings/policies for operating systems on premise to align with the Authentication and Authorization Standard. Exception to authentication configurations must be approved by the CISO. | C24: C13-03 | D24: Control owner's completeness & accuracy check over the server inventory (e.g., reconciliation to Active Directory / virtualization console). | E24: ='Coverage Period'!K8 -> 07/05/2025 - 01/04/2026 | F24: 2. Report Completeness & Accuracy | G24: New for 2026 (NewTest Script step 2) | H24: Ian Rojo
A25: BSI.IT.10.C13 | B25: [BSI.IT.10.C13 Config Authentication] In every operation, Infrastructure Engineering have configured strong authentication settings/policies for operating systems on premise to align with the Authentication and Authorization Standard. Exception to authentication configurations must be approved by the CISO. | C25: C13-04 | D25: For each Windows server sample selected by IT RCSA: security export (secedit /export /cfg c:\security_export.txt) and/or applied GPO (gpresult /h) showing MinimumPasswordLength, PasswordComplexity, MinimumPasswordAge, MaximumPasswordAge, PasswordHistorySize, LockoutBadCount, LockoutDuration, ResetLockoutCount and idle session timeout. File name must contain the server name. | E25: ='Coverage Period'!K8 -> 07/05/2025 - 01/04/2026 | F25: 4. Control Execution | G25: BSI.IT.10.C13.05 Windows samples password.zip | H25: Ian Rojo
A26: BSI.IT.10.C13 | B26: [BSI.IT.10.C13 Config Authentication] In every operation, Infrastructure Engineering have configured strong authentication settings/policies for operating systems on premise to align with the Authentication and Authorization Standard. Exception to authentication configurations must be approved by the CISO. | C26: C13-05 | D26: For each RHEL server sample: contents of /etc/login.defs, /etc/security/pwquality.conf, /etc/pam.d/system-auth and /etc/pam.d/password-auth (faillock deny / unlock_time, pwhistory remember) and the idle timeout setting (TMOUT in /etc/profile or /etc/profile.d), with hostname and date visible. | E26: ='Coverage Period'!K8 -> 07/05/2025 - 01/04/2026 | F26: 4. Control Execution | G26: BSI.IT.10.C13.06 Linux samples | H26: Ian Rojo
A27: BSI.IT.10.C13 | B27: [BSI.IT.10.C13 Config Authentication] In every operation, Infrastructure Engineering have configured strong authentication settings/policies for operating systems on premise to align with the Authentication and Authorization Standard. Exception to authentication configurations must be approved by the CISO. | C27: C13-06 | D27: List of authentication configuration exceptions in effect during the coverage period with CISO approval evidence and business justification. If none, written confirmation. | E27: ='Coverage Period'!K8 -> 07/05/2025 - 01/04/2026 | F27: 6. Exception Handling | G27: 2025: exceptions noted without CISO approval | H27: Ian Rojo
A28: BSI.IT.10.C13 | B28: [BSI.IT.10.C13 Config Authentication] In every operation, Infrastructure Engineering have configured strong authentication settings/policies for operating systems on premise to align with the Authentication and Authorization Standard. Exception to authentication configurations must be approved by the CISO. | C28: C13-07 | D28: Remediation evidence for open Action Driver 005056BCA24E1FD0B4A6A1173BF00BA4 (2025 RCSA - Config Authentication Exceptions): change tickets and configuration evidence that Windows AccountLockoutDuration was set to 15 minutes or more and idle session timeout was defined; current AD status and target date. | E28: ='Coverage Period'!K8 -> 07/05/2025 - 01/04/2026 | F28: 7. Escalation & Remediation | G28: 2025 exceptions: AccountLockoutDuration = -1 on 10 Windows servers; idle timeout not defined | H28: Ian Rojo
A29: BSI.IT.10.C18 | B29: [BSI.IT.10.C18 Endpoint Protection] In every operation and upon imaging of a user computer, EUT installs Endpoint Protection on the user computers to detect and quarantine malicious software. Exceptions to disable malware protections on user computers are approved by the CISO (or delegate). | C29: C18-01 | D29: EUT imaging / endpoint build procedure showing installation of Endpoint Protection (CrowdStrike Falcon) on user computers, and the process to request and approve exceptions to disable malware protection (CISO or delegate). | E29: ='Coverage Period'!K9 -> 07/05/2025 - 07/04/2026 | F29: 1. Obtain Evidence | G29: 2025 WP2 control description | H29: Cesar Rubio
A30: BSI.IT.10.C18 | B30: [BSI.IT.10.C18 Endpoint Protection] In every operation and upon imaging of a user computer, EUT installs Endpoint Protection on the user computers to detect and quarantine malicious software. Exceptions to disable malware protections on user computers are approved by the CISO (or delegate). | C30: C18-02 | D30: Screenshot of the BigFix action configured to deploy the CrowdStrike Windows Sensor to workstations and laptops when the agent is not found (e.g., 'PERMANENT ACTION - SOFTWARE_DEPLOYMENT_CROWDSTRIKE_WINDOWS_SENSOR'), showing status, targeting/relevance, expiration (never expires) and last-modified date. | E30: ='Coverage Period'!K9 -> 07/05/2025 - 07/04/2026 | F30: 4. Control Execution | G30: BSI.IT.10.C18.02 CS Installed | H30: Cesar Rubio
A31: BSI.IT.10.C18 | B31: [BSI.IT.10.C18 Endpoint Protection] In every operation and upon imaging of a user computer, EUT installs Endpoint Protection on the user computers to detect and quarantine malicious software. Exceptions to disable malware protections on user computers are approved by the CISO (or delegate). | C31: C18-03 | D31: Screenshot of the workstation image / task sequence showing the CrowdStrike sensor installation step (if included in the image). | E31: ='Coverage Period'!K9 -> 07/05/2025 - 07/04/2026 | F31: 4. Control Execution | G31: New for 2026 - 'upon imaging' attribute | H31: Cesar Rubio
A32: BSI.IT.10.C18 | B32: [BSI.IT.10.C18 Endpoint Protection] In every operation and upon imaging of a user computer, EUT installs Endpoint Protection on the user computers to detect and quarantine malicious software. Exceptions to disable malware protections on user computers are approved by the CISO (or delegate). | C32: C18-04 | D32: CrowdStrike Falcon prevention policy applied to BSI workstations showing detection and quarantine settings enabled (e.g., Quarantine & Security Center Registration, ML prevention, Quarantine on write). | E32: ='Coverage Period'!K9 -> 07/05/2025 - 07/04/2026 | F32: 5. Control Results | G32: New for 2026 - 'detect and quarantine' attribute | H32: Cesar Rubio
A33: BSI.IT.10.C18 | B33: [BSI.IT.10.C18 Endpoint Protection] In every operation and upon imaging of a user computer, EUT installs Endpoint Protection on the user computers to detect and quarantine malicious software. Exceptions to disable malware protections on user computers are approved by the CISO (or delegate). | C33: C18-05 | D33: System-generated list of user computers imaged during the coverage period (SCCM/Intune/BigFix): device name, image date. Include query/filter screenshot and run date (IPE). | E33: ='Coverage Period'!K9 -> 07/05/2025 - 07/04/2026 | F33: 3. Population & Scope | G33: New for 2026 | H33: Cesar Rubio
A34: BSI.IT.10.C18 | B34: [BSI.IT.10.C18 Endpoint Protection] In every operation and upon imaging of a user computer, EUT installs Endpoint Protection on the user computers to detect and quarantine malicious software. Exceptions to disable malware protections on user computers are approved by the CISO (or delegate). | C34: C18-06 | D34: CrowdStrike Falcon host management export for BSI workstations/laptops as of the request date (hostname, first seen, last seen, sensor version, prevention policy) and the control owner's reconciliation to the imaged-device list / AD computer objects identifying any devices without the agent. | E34: ='Coverage Period'!K9 -> 07/05/2025 - 07/04/2026 | F34: 2. Report Completeness & Accuracy | G34: New for 2026 (NewTest Script step 2-3) | H34: Cesar Rubio
A35: BSI.IT.10.C18 | B35: [BSI.IT.10.C18 Endpoint Protection] In every operation and upon imaging of a user computer, EUT installs Endpoint Protection on the user computers to detect and quarantine malicious software. Exceptions to disable malware protections on user computers are approved by the CISO (or delegate). | C35: C18-07 | D35: For each device sample selected by IT RCSA: Falcon console host-detail screenshot showing sensor installed and active, sensor version and first-seen date relative to the image date. | E35: ='Coverage Period'!K9 -> 07/05/2025 - 07/04/2026 | F35: 5. Control Results | G35: New for 2026 | H35: Cesar Rubio
A36: BSI.IT.10.C18 | B36: [BSI.IT.10.C18 Endpoint Protection] In every operation and upon imaging of a user computer, EUT installs Endpoint Protection on the user computers to detect and quarantine malicious software. Exceptions to disable malware protections on user computers are approved by the CISO (or delegate). | C36: C18-08 | D36: List of user computers with malware protection disabled, sensor removed or placed in an exclusion/bypass group during the coverage period, with CISO (or delegate) approval. If none, written confirmation. | E36: ='Coverage Period'!K9 -> 07/05/2025 - 07/04/2026 | F36: 6. Exception Handling | G36: 2025: none noted | H36: Cesar Rubio
A37: BSI.IT.10.C18 | B37: [BSI.IT.10.C18 Endpoint Protection] In every operation and upon imaging of a user computer, EUT installs Endpoint Protection on the user computers to detect and quarantine malicious software. Exceptions to disable malware protections on user computers are approved by the CISO (or delegate). | C37: C18-09 | D37: Tickets for devices found without the agent or with the agent disabled during the coverage period, with remediation evidence. Change history for the BigFix action and Falcon prevention policy during the period. | E37: ='Coverage Period'!K9 -> 07/05/2025 - 07/04/2026 | F37: 7. Escalation & Remediation | G37: New for 2026 | H37: Cesar Rubio
A38: BSI.IT.10.C19 | B38: [BSI.IT.10.C19 Server Protection] In every operation and upon imaging of a server, Infrastructure Engineering installs Endpoint Protection on the server to mitigate the risk of any malicious software. Exceptions to disable malware protections on server are approved by the CISO (or delegate). | C38: C19-01 | D38: Server build / imaging procedures (Windows and RHEL) showing installation of Endpoint Protection (CrowdStrike Falcon) on servers, and the process to request and approve exceptions to disable malware protection (CISO or delegate). | E38: ='Coverage Period'!K10 -> 07/05/2025 - 07/04/2026 | F38: 1. Obtain Evidence | G38: 2025 WP2 Test Procedure | H38: Ian Rojo
A39: BSI.IT.10.C19 | B39: [BSI.IT.10.C19 Server Protection] In every operation and upon imaging of a server, Infrastructure Engineering installs Endpoint Protection on the server to mitigate the risk of any malicious software. Exceptions to disable malware protections on server are approved by the CISO (or delegate). | C39: C19-02 | D39: System-generated ServiceNow / CMDB query of ALL BSI Windows and Linux (RHEL) servers created during the coverage period: server name, OS, environment, created date, install status. Include screenshot of query/filters, run date and run-by user (IPE). | E39: ='Coverage Period'!K10 -> 07/05/2025 - 07/04/2026 | F39: 3. Population & Scope | G39: BSI.IT.10.C19.05 Linux Server Population sample and Query | H39: Ian Rojo
A40: BSI.IT.10.C19 | B40: [BSI.IT.10.C19 Server Protection] In every operation and upon imaging of a server, Infrastructure Engineering installs Endpoint Protection on the server to mitigate the risk of any malicious software. Exceptions to disable malware protections on server are approved by the CISO (or delegate). | C40: C19-03 | D40: CrowdStrike Falcon host management export for BSI servers as of the request date (hostname, OS, first seen, last seen, sensor version, prevention policy) and the control owner's reconciliation of the new-server population to the Falcon export. | E40: ='Coverage Period'!K10 -> 07/05/2025 - 07/04/2026 | F40: 2. Report Completeness & Accuracy | G40: New for 2026 (NewTest Script steps 2-3) | H40: Ian Rojo
A41: BSI.IT.10.C19 | B41: [BSI.IT.10.C19 Server Protection] In every operation and upon imaging of a server, Infrastructure Engineering installs Endpoint Protection on the server to mitigate the risk of any malicious software. Exceptions to disable malware protections on server are approved by the CISO (or delegate). | C41: C19-04 | D41: Windows: screenshot of the BigFix action configured to deploy the CrowdStrike Windows Sensor to servers when the agent is not found (status, targeting, never-expires, last modified) and the server image/boot sequence showing the sensor installed. | E41: ='Coverage Period'!K10 -> 07/05/2025 - 07/04/2026 | F41: 4. Control Execution | G41: BSI.IT.10.C19.03 Testing to show CS agent install | H41: Ian Rojo
...

Sheet Summary
A1: DRL Summary by Control
A3: Control # | B3: Control Name | C3: Control Owner | D3: Heracles ID | E3: Nature | F3: Inherent Risk | G3: Coverage Period | H3: # Requests | I3: # Provided / Closed | J3: # Open
A4: BSI.IT.10.C11 | B4: Vendor Defaults | C4: Ian Rojo | D4: 50539549 | E4: Hybrid / Semi-Automated | F4: High | G4: ='Coverage Period'!K6 -> 07/01/2025 - 06/30/2026 | H4: =COUNTIF(DRL!$A$5:$A$53,A4) -> 8 | I4: =COUNTIFS(DRL!$A$5:$A$53,A4,DRL!$J$5:$J$53,"Provided")+COUNTIFS(DRL!$A$5:$A$53,A4,DRL!$J$5:$J$53,"Closed") -> 0 | J4: =H4-I4 -> 8
A5: BSI.IT.10.C12 | B5: Encrypt Endpoint Device | C5: Cesar Rubio | D5: 50539550 | E5: Automated | F5: High | G5: ='Coverage Period'!K7 -> 06/01/2025 - 05/31/2026 | H5: =COUNTIF(DRL!$A$5:$A$53,A5) -> 9 | I5: =COUNTIFS(DRL!$A$5:$A$53,A5,DRL!$J$5:$J$53,"Provided")+COUNTIFS(DRL!$A$5:$A$53,A5,DRL!$J$5:$J$53,"Closed") -> 0 | J5: =H5-I5 -> 9
A6: BSI.IT.10.C13 | B6: Config Authentication | C6: Ian Rojo | D6: 50539552 | E6: Hybrid / Semi-Automated | F6: High | G6: ='Coverage Period'!K8 -> 07/05/2025 - 01/04/2026 | H6: =COUNTIF(DRL!$A$5:$A$53,A6) -> 7 | I6: =COUNTIFS(DRL!$A$5:$A$53,A6,DRL!$J$5:$J$53,"Provided")+COUNTIFS(DRL!$A$5:$A$53,A6,DRL!$J$5:$J$53,"Closed") -> 0 | J6: =H6-I6 -> 7
A7: BSI.IT.10.C18 | B7: Endpoint Protection | C7: Cesar Rubio | D7: 50539666 | E7: Automated | F7: High | G7: ='Coverage Period'!K9 -> 07/05/2025 - 07/04/2026 | H7: =COUNTIF(DRL!$A$5:$A$53,A7) -> 9 | I7: =COUNTIFS(DRL!$A$5:$A$53,A7,DRL!$J$5:$J$53,"Provided")+COUNTIFS(DRL!$A$5:$A$53,A7,DRL!$J$5:$J$53,"Closed") -> 0 | J7: =H7-I7 -> 9
A8: BSI.IT.10.C19 | B8: Server Protection | C8: Ian Rojo | D8: 50539667 | E8: Hybrid / Semi-Automated | F8: High | G8: ='Coverage Period'!K10 -> 07/05/2025 - 07/04/2026 | H8: =COUNTIF(DRL!$A$5:$A$53,A8) -> 8 | I8: =COUNTIFS(DRL!$A$5:$A$53,A8,DRL!$J$5:$J$53,"Provided")+COUNTIFS(DRL!$A$5:$A$53,A8,DRL!$J$5:$J$53,"Closed") -> 0 | J8: =H8-I8 -> 8
A9: SBNA.IT.10.C14 | B9: MDM Config | C9: Jean Paul Merymo | D9: 50418562 | E9: Automated | F9: Moderate | G9: ='Coverage Period'!K11 -> 06/01/2025 - 05/31/2026 | H9: =COUNTIF(DRL!$A$5:$A$53,A9) -> 8 | I9: =COUNTIFS(DRL!$A$5:$A$53,A9,DRL!$J$5:$J$53,"Provided")+COUNTIFS(DRL!$A$5:$A$53,A9,DRL!$J$5:$J$53,"Closed") -> 0 | J9: =H9-I9 -> 8
A10: Total | H10: =SUM(H4:H9) -> 49 | I10: =SUM(I4:I9) -> 0 | J10: =SUM(J4:J9) -> 49

Sheet Coverage Period
A1: Coverage Period Calculation - 2026 IT RCSA Cycle 1 (scheduled 05/04/2026 - 06/12/2026)
A2: Rule (RCSA Testing Procedure (CUSO) 07.17.2026, s.4.4.2 Population and Sampling): Annual tests = 12-month population timeframe; Semi-Annual tests = 6-month timeframe. The start date is the day after the last day of the previous testing timeframe (2025 WP2 > Control Performance Assessment > Population Timeframe).
A3: Yellow cells are inputs - edit the Prior Timeframe End Date or Months and the coverage period (and the DRL tab) recalculate. Shaded rows need confirmation (see Notes).
A5: Control # | B5: Control Name | C5: 2025 WP2 Population Timeframe | D5: 2025 WP2 Test Date | E5: Last GRC Assessment (Rating) | F5: Prior Timeframe End Date | G5: 2026 Assessment Testing Frequency | H5: Months in Timeframe | I5: Coverage Start | J5: Coverage End | K5: Coverage Period | L5: Notes
A6: BSI.IT.10.C11 | B6: Vendor Defaults | C6: 10/1/2024 - 6/30/2025 | D6: 07/10/2025 | E6: 12/22/2025 (Satisfactory) | F6: 45838 | G6: Annual | H6: 12 | I6: =F6+1 -> 45839 | J6: =EDATE(I6,H6)-1 -> 46203 | K6: =TEXT(I6,"mm/dd/yyyy")&" - "&TEXT(J6,"mm/dd/yyyy") -> 07/01/2025 - 06/30/2026 | L6: CONFIRM: WP2 provided is 2025 Cycle 1 (test date 7/10/2025). GRC shows a later assessment on 12/22/2025 (2025 Cycle 2, remaining samples). If that Cycle 2 population ran past 6/30/2025, change the Prior Timeframe End Date to its end date - coverage recalculates. 2026 statement now scopes to OS root/administrator accounts only; Oracle/SQL DB defaults tested in 2025 now sit under BSI.IT.10.C10.
A7: BSI.IT.10.C12 | B7: Encrypt Endpoint Device | C7: 10/1/2024 - 5/31/2025 | D7: 07/09/2025 | E7: 07/15/2025 (Strong) | F7: 45808 | G7: Annual | H7: 12 | I7: =F7+1 -> 45809 | J7: =EDATE(I7,H7)-1 -> 46173 | K7: =TEXT(I7,"mm/dd/yyyy")&" - "&TEXT(J7,"mm/dd/yyyy") -> 06/01/2025 - 05/31/2026 | L7: 2026 statement changed from 2025 ('during the imaging process (Windows) or assignment (MAC)') to 'prior to assigning a user a computer ... approved encryption algorithms and lengths' - request now includes the assignment-date attribute and the approved-algorithm standard.
A8: BSI.IT.10.C13 | B8: Config Authentication | C8: 10/01/2024 - 7/4/2025 | D8: 07/10/2025 | E8: 12/19/2025 (Weak - Ineffective) | F8: 45842 | G8: Semi-Annual | H8: 6 | I8: =F8+1 -> 45843 | J8: =EDATE(I8,H8)-1 -> 46026 | K8: =TEXT(I8,"mm/dd/yyyy")&" - "&TEXT(J8,"mm/dd/yyyy") -> 07/05/2025 - 01/04/2026 | L8: CONFIRM: Control is Semi-Annual (Weak on 12/19/2025) with open Action Driver 005056BCA24E1FD0B4A6A1173BF00BA4 (target 9/30/2026). Per RCSA Testing Procedure s.4.1.3, CPA cannot be performed while an AD is open - confirm with Testing Manager whether this is CPA or sustainability testing. WP2 provided is 2025 Cycle 1; if the 12/19/2025 Cycle 2 population ran past 7/4/2025, update the Prior Timeframe End Date.
A9: BSI.IT.10.C18 | B9: Endpoint Protection | C9: 10/1/2024 - 7/4/2025 | D9: 07/01/2025 | E9: 08/06/2025 (Strong) | F9: 45842 | G9: Annual | H9: 12 | I9: =F9+1 -> 45843 | J9: =EDATE(I9,H9)-1 -> 46207 | K9: =TEXT(I9,"mm/dd/yyyy")&" - "&TEXT(J9,"mm/dd/yyyy") -> 07/05/2025 - 07/04/2026 | L9: Coverage end (7/4/2026) falls after the Cycle 1 window (5/4/2026 - 6/12/2026): population is pulled through the date of the request; any remaining days roll into the next timeframe.
A10: BSI.IT.10.C19 | B10: Server Protection | C10: 10/01/2024 - 7/4/2025 | D10: 07/10/2025 | E10: 08/14/2025 (Satisfactory) | F10: 45842 | G10: Annual | H10: 12 | I10: =F10+1 -> 45843 | J10: =EDATE(I10,H10)-1 -> 46207 | K10: =TEXT(I10,"mm/dd/yyyy")&" - "&TEXT(J10,"mm/dd/yyyy") -> 07/05/2025 - 07/04/2026 | L10: Coverage end (7/4/2026) falls after the Cycle 1 window (5/4/2026 - 6/12/2026): population is pulled through the date of the request; any remaining days roll into the next timeframe.
A11: SBNA.IT.10.C14 | B11: MDM Config | C11: 10/1/2024 - 5/31/2025 | D11: 06/06/2025 | E11: 07/02/2025 (Satisfactory) | F11: 45808 | G11: Annual | H11: 12 | I11: =F11+1 -> 45809 | J11: =EDATE(I11,H11)-1 -> 46173 | K11: =TEXT(I11,"mm/dd/yyyy")&" - "&TEXT(J11,"mm/dd/yyyy") -> 06/01/2025 - 05/31/2026 | L11: Entities in scope: SBNA, SC, BSI, BSNY, SANCAP. BSI does not participate in BYOD (per 2025 WP2).

Sheet Source Mapping
A1: Sources Used to Build the DRL
A3: Control # | B3: 2026 Control Statement Source | C3: Test Script Source (IT RCSA 2026 Test Plan > New test scripts) | D3: Prior Evidence Source | E3: Coverage Period Source
A4: BSI.IT.10.C11 | B4: IT RCSA 2026 Test Plan > Control Inventory (Control Description), agrees to Export tab (GRC). | C4: No exact match in 'New test scripts'. Script structure taken from BSI.IT.10.C10 Vendor Defaults DB (row 76) - same Vendor Defaults family - and tailored to OS root/administrator accounts. | D4: WP2 BSI.IT.10.C11 Vendor Defaults.xlsm > Control Performance Assessment (Test Procedure, Summary of Results, Supporting Evidence per Attribute). | E4: WP2 Population Timeframe 10/1/2024 - 6/30/2025 + RCSA Testing Procedure (CUSO) 07.17.2026 s.4.4.2; frequency from 2026 Test Plan Export tab (Annual).
A5: BSI.IT.10.C12 | B5: IT RCSA 2026 Test Plan > Control Inventory (Control Description), agrees to Export tab (GRC). | C5: No exact or analog match in 'New test scripts'. Requests follow the standard 9-step NewTest Script structure (Obtain Evidence > Report C&A > Population > Execution > Results > Exceptions > Escalation). | D5: WP2 BSI.IT.10.C12 Encrypt Endpoint Device.xlsm > Control Performance Assessment (Test Procedure, Summary of Results, Supporting Evidence per Attribute). | E5: WP2 Population Timeframe 10/1/2024 - 5/31/2025 + RCSA Testing Procedure (CUSO) 07.17.2026 s.4.4.2; frequency from 2026 Test Plan Export tab (Annual).
A6: BSI.IT.10.C13 | B6: IT RCSA 2026 Test Plan > Control Inventory (Control Description), agrees to Export tab (GRC). | C6: Matched to SBNA.IT.10.C13 Config Authentication (row 79) - identical control statement for the SBNA entity. | D6: WP2 BSI.IT.10.C13 Config Authentication.xlsm > Control Performance Assessment (Test Procedure, Summary of Results, Supporting Evidence per Attribute). | E6: WP2 Population Timeframe 10/01/2024 - 7/4/2025 + RCSA Testing Procedure (CUSO) 07.17.2026 s.4.4.2; frequency from 2026 Test Plan Export tab (Semi-Annual).
A7: BSI.IT.10.C18 | B7: IT RCSA 2026 Test Plan > Control Inventory (Control Description), agrees to Export tab (GRC). | C7: No exact match in 'New test scripts'. Script structure adapted from SBNA.IT.10.C19 Server Protection (row 81) - same CrowdStrike / BigFix endpoint protection mechanism, applied to user computers. | D7: WP2 BSI.IT.10.C18 Endpoint Protection.xlsm > Control Performance Assessment (Test Procedure, Summary of Results, Supporting Evidence per Attribute). | E7: WP2 Population Timeframe 10/1/2024 - 7/4/2025 + RCSA Testing Procedure (CUSO) 07.17.2026 s.4.4.2; frequency from 2026 Test Plan Export tab (Annual).
A8: BSI.IT.10.C19 | B8: IT RCSA 2026 Test Plan > Control Inventory (Control Description), agrees to Export tab (GRC). | C8: Matched to SBNA.IT.10.C19 Server Protection (row 81) - identical control statement for the SBNA entity. | D8: WP2 BSI.IT.10.C19 Server Protection.xlsm > Control Performance Assessment (Test Procedure, Summary of Results, Supporting Evidence per Attribute). | E8: WP2 Population Timeframe 10/01/2024 - 7/4/2025 + RCSA Testing Procedure (CUSO) 07.17.2026 s.4.4.2; frequency from 2026 Test Plan Export tab (Annual).
A9: SBNA.IT.10.C14 | B9: IT RCSA 2026 Test Plan > Control Inventory (Control Description), agrees to Export tab (GRC). | C9: No exact or analog match in 'New test scripts' (SBNA.IT.5.C11b MDM Access Mgmt is a different access-management control). Requests follow the standard 9-step NewTest Script structure and the 2025 configuration attribute list. | D9: WP2 SBNA.IT.10.C14 MDM Config.xlsm > Control Performance Assessment (Test Procedure, Summary of Results, Supporting Evidence per Attribute). | E9: WP2 Population Timeframe 10/1/2024 - 5/31/2025 + RCSA Testing Procedure (CUSO) 07.17.2026 s.4.4.2; frequency from 2026 Test Plan Export tab (Annual).
A11: Other references
A12: RCSA Testing Procedure s.4.4.5 Evidence Request - population and sample requests are sent to the BU BCO / control owner via the DRL.
A13: RCSA Testing Procedure s.4.1.3 - controls with open Action Drivers cannot be tested for CDA/CPA until remediation is complete (applies to BSI.IT.10.C13).
A14: RCSA Testing Procedure Appendix (Key Reports / IPE) - capture report name, parameters (date range, filters) and completeness & accuracy validation for population reports.
A15: NewTest Script 9-step structure: 1 Obtain Evidence, 2 Report Completeness & Accuracy, 3 Population & Scope, 4 Control Execution, 5 Control Results, 6 Exception Handling, 7 Escalation & Remediation, 8 Risk Mitigation, 9 Testing Coverage (steps 8-9 are tester conclusions, no evidence request).
